Workbook

Sheet Equipment
A1: Equipment and measurement uncertainties
A3: Instruments
A4: Instrument | B4: Role / Channel | C4: Model | D4: Serial no. | E4: Ratio / Range | F4: Uncertainty (±%) | G4: Last calibration
A5: High-voltage probe | B5: CH1 — secondary
A6: Current probe | B6: CH2 — secondary
A7: Voltage probe | B7: CH3 — primary
A8: Oscilloscope | B8: Power analysis / FFT
A9: FLIR thermal camera | B9: T_transformer
A10: Thermocouple + multimeter | B10: T_heatsink
A11: Power supply (buck) | B11: V_buck / I_primary
A12: HV transformer | B12: Voltage step-up
A13: DBD reactor | B13: Load (gap, dielectric)
A15: Uncertainty parameters (used by Data_consolidated)
A16: u(V_secondary) ±% | B16: 3
A17: u(I_secondary) ±% | B17: 5
A18: u(P_input) ±% | B18: 5
A19: u(P_real) ±% | B19: 6

Sheet Exp 1 - Probe_Characterization
A1: Exp 1 - Probe characterization (open circuit)
A2: CONDITIONS | I2: PRIMARY | N2: HV SECONDARY | R2: POWER | AA2: SIGNAL QUALITY | AM2: PHYSICAL STATE | AQ2: TRACEABILITY
A3: Block | B3: Step | C3: Mode | D3: Turns/branch | E3: Frequency (kHz) | F3: Burst Frequency (kHz) | G3: DutyCycle (%) | H3: V_Buck setpoint (V) | I3: V_Buck_Average (V) | J3: V_Buck_Ripple (mV) | K3: Relative_Ripple (%) | L3: I_primary (A) | M3: P_input (W) | N3: V_secondary_pp (kV) | O3: V_secondary_RMS (kV) | P3: I_sec_RMS (mA) | Q3: Load_Impedance (Ohm) | R3: VxI_RMS (W) | S3: Apparent Power (VA) | T3: Phase Angle° | U3: Power factor | V3: Real Power(W) | W3: Loss fraction (1-η) | X3: Real Power_scope (W) | Y3: Power Factor_scope | Z3: cos(φ) vs scope deviation (%) | AA3: THD (%) | AB3: Waveform | AC3: V1 (Vrms) | AD3: V2 | AE3: V3 | AF3: V4 | AG3: V5 | AH3: V6 | AI3: V7 | AJ3: V8 | AK3: V9 | AL3: V10 | AM3: T_MOSFET (°C) | AN3: Stability | AO3: Plasma state | AP3: Ignition threshold? | AQ3: Photo | AR3: Observations
A4: BLOCK 1 — Probe load (open circuit) · V-sweep · 20 kHz · DC 100% · SQUARE (10 steps)
A5: BLOCK 1 | B5: 1 | C5: SQUARE | E5: 20 | G5: 100 | H5: 1 | I5: 0.988 | J5: 87 | K5: =IF(COUNT(J5,I5)=0,"",IFERROR(J5/1000/I5,"")) -> 0.08805668 | L5: 0.38 | M5: =IF(COUNT(H5,L5)=0,"",IFERROR(H5*L5,"")) -> 0.38 | N5: 1.68 | O5: 0.549 | P5: 0.661 | Q5: =IF(COUNT(O5,P5)=0,"",IFERROR(O5*1000/P5*1000,"")) -> 830559.76 | S5: =IF(COUNT(O5,P5)=0,"",IFERROR(O5*P5,"")) -> 0.362889 | T5: 72.9 | U5: =IF(COUNT(T5)=0,"",IFERROR(COS(T5/180*PI()),"")) -> 0.29404033 | V5: =IF(COUNT(S5,T5)=0,"",IFERROR(S5*COS(T5/360*2*3.14),"")) -> 0.1069277 | W5: =IF(COUNT(V5,M5)=0,"",IFERROR(1-V5/M5,"")) -> 0.71861131 | Z5: =IFERROR(IF(OR(V5="",X5="",X5=0),"",(V5-X5)/X5*100),"") | AA5: =IF(COUNT(AD5,AE5,AF5,AG5,AH5,AI5,AJ5,AK5,AL5,AC5)=0,"",IFERROR(SQRT(AD5^2+AE5^2+AF5^2+AG5^2+AH5^2+AI5^2+AJ5^2+AK5^2+AL5^2)/AC5,"")) -> 0.11278756 | AC5: 527 | AD5: 44 | AE5: 36 | AF5: 12 | AG5: 11 | AH5: 6 | AM5: 26
A6: BLOCK 1 | B6: 2 | C6: SQUARE | E6: 20 | G6: 100 | H6: 2 | I6: 2 | J6: 128 | K6: =IF(COUNT(J6,I6)=0,"",IFERROR(J6/1000/I6,"")) -> 0.064 | L6: 0.55 | M6: =IF(COUNT(H6,L6)=0,"",IFERROR(H6*L6,"")) -> 1.1 | N6: 2.43 | O6: 0.757 | P6: 0.912 | Q6: =IF(COUNT(O6,P6)=0,"",IFERROR(O6*1000/P6*1000,"")) -> 830043.86 | S6: =IF(COUNT(O6,P6)=0,"",IFERROR(O6*P6,"")) -> 0.690384 | T6: 73.9 | U6: =IF(COUNT(T6)=0,"",IFERROR(COS(T6/180*PI()),"")) -> 0.27731465 | V6: =IF(COUNT(S6,T6)=0,"",IFERROR(S6*COS(T6/360*2*3.14),"")) -> 0.19188728 | W6: =IF(COUNT(V6,M6)=0,"",IFERROR(1-V6/M6,"")) -> 0.82555702 | Z6: =IFERROR(IF(OR(V6="",X6="",X6=0),"",(V6-X6)/X6*100),"") | AA6: =IF(COUNT(AD6,AE6,AF6,AG6,AH6,AI6,AJ6,AK6,AL6,AC6)=0,"",IFERROR(SQRT(AD6^2+AE6^2+AF6^2+AG6^2+AH6^2+AI6^2+AJ6^2+AK6^2+AL6^2)/AC6,"")) -> 0.10703822 | AC6: 723 | AD6: 60 | AE6: 42 | AF6: 20 | AG6: 12 | AH6: 9 | AM6: 30
A7: BLOCK 1 | B7: 3 | C7: SQUARE | E7: 20 | G7: 100 | H7: 3 | I7: 2.99 | J7: 132 | K7: =IF(COUNT(J7,I7)=0,"",IFERROR(J7/1000/I7,"")) -> 0.044147157 | L7: 0.75 | M7: =IF(COUNT(H7,L7)=0,"",IFERROR(H7*L7,"")) -> 2.25 | N7: 3.38 | O7: 1.08 | P7: 1.32 | Q7: =IF(COUNT(O7,P7)=0,"",IFERROR(O7*1000/P7*1000,"")) -> 818181.82 | S7: =IF(COUNT(O7,P7)=0,"",IFERROR(O7*P7,"")) -> 1.4256 | T7: 73.5 | U7: =IF(COUNT(T7)=0,"",IFERROR(COS(T7/180*PI()),"")) -> 0.28401534 | V7: =IF(COUNT(S7,T7)=0,"",IFERROR(S7*COS(T7/360*2*3.14),"")) -> 0.40578113 | W7: =IF(COUNT(V7,M7)=0,"",IFERROR(1-V7/M7,"")) -> 0.81965283 | Z7: =IFERROR(IF(OR(V7="",X7="",X7=0),"",(V7-X7)/X7*100),"") | AA7: =IF(COUNT(AD7,AE7,AF7,AG7,AH7,AI7,AJ7,AK7,AL7,AC7)=0,"",IFERROR(SQRT(AD7^2+AE7^2+AF7^2+AG7^2+AH7^2+AI7^2+AJ7^2+AK7^2+AL7^2)/AC7,"")) -> 0.13592899 | AC7: 1031 | AD7: 101 | AE7: 89 | AF7: 30 | AG7: 18 | AH7: 13 | AI7: 8 | AJ7: 6 | AK7: 5 | AM7: 35
A8: BLOCK 1 | B8: 4 | C8: SQUARE | E8: 20 | G8: 100 | H8: 4 | I8: 3.97 | J8: 406 | K8: =IF(COUNT(J8,I8)=0,"",IFERROR(J8/1000/I8,"")) -> 0.102267 | L8: 1.69 | M8: =IF(COUNT(H8,L8)=0,"",IFERROR(H8*L8,"")) -> 6.76 | N8: 8.15 | O8: 2.69 | P8: 3.25 | Q8: =IF(COUNT(O8,P8)=0,"",IFERROR(O8*1000/P8*1000,"")) -> 827692.31 | S8: =IF(COUNT(O8,P8)=0,"",IFERROR(O8*P8,"")) -> 8.7425 | T8: 74.4 | U8: =IF(COUNT(T8)=0,"",IFERROR(COS(T8/180*PI()),"")) -> 0.26891982 | V8: =IF(COUNT(S8,T8)=0,"",IFERROR(S8*COS(T8/360*2*3.14),"")) -> 2.3565742 | W8: =IF(COUNT(V8,M8)=0,"",IFERROR(1-V8/M8,"")) -> 0.65139435 | Z8: =IFERROR(IF(OR(V8="",X8="",X8=0),"",(V8-X8)/X8*100),"") | AA8: =IF(COUNT(AD8,AE8,AF8,AG8,AH8,AI8,AJ8,AK8,AL8,AC8)=0,"",IFERROR(SQRT(AD8^2+AE8^2+AF8^2+AG8^2+AH8^2+AI8^2+AJ8^2+AK8^2+AL8^2)/AC8,"")) -> 0.12712097 | AC8: 2515 | AD8: 225 | AE8: 187 | AF8: 100 | AG8: 60 | AH8: 39 | AI8: 29 | AJ8: 17 | AK8: 15 | AL8: 12 | AM8: 47
A9: BLOCK 1 | B9: 5 | C9: SQUARE | E9: 20 | G9: 100 | H9: 5 | I9: 4.85 | J9: 496 | K9: =IF(COUNT(J9,I9)=0,"",IFERROR(J9/1000/I9,"")) -> 0.10226804 | L9: 2.16 | M9: =IF(COUNT(H9,L9)=0,"",IFERROR(H9*L9,"")) -> 10.8 | N9: 11.45 | O9: 4.06 | P9: 4.78 | Q9: =IF(COUNT(O9,P9)=0,"",IFERROR(O9*1000/P9*1000,"")) -> 849372.38 | S9: =IF(COUNT(O9,P9)=0,"",IFERROR(O9*P9,"")) -> 19.4068 | T9: 73.7 | U9: =IF(COUNT(T9)=0,"",IFERROR(COS(T9/180*PI()),"")) -> 0.28066671 | V9: =IF(COUNT(S9,T9)=0,"",IFERROR(S9*COS(T9/360*2*3.14),"")) -> 5.4589881 | W9: =IF(COUNT(V9,M9)=0,"",IFERROR(1-V9/M9,"")) -> 0.49453814 | Z9: =IFERROR(IF(OR(V9="",X9="",X9=0),"",(V9-X9)/X9*100),"") | AA9: =IF(COUNT(AD9,AE9,AF9,AG9,AH9,AI9,AJ9,AK9,AL9,AC9)=0,"",IFERROR(SQRT(AD9^2+AE9^2+AF9^2+AG9^2+AH9^2+AI9^2+AJ9^2+AK9^2+AL9^2)/AC9,"")) -> 0.091097888 | AC9: 3825 | AD9: 307 | AE9: 138 | AF9: 70 | AG9: 44 | AH9: 28 | AI9: 14 | AJ9: 12 | AK9: 10 | AL9: 8 | AM9: 52
A10: BLOCK 1 | B10: 6 | C10: SQUARE | E10: 20 | G10: 100 | H10: 6 | I10: 5.86 | J10: 685 | K10: =IF(COUNT(J10,I10)=0,"",IFERROR(J10/1000/I10,"")) -> 0.1168942 | L10: 2.23 | M10: =IF(COUNT(H10,L10)=0,"",IFERROR(H10*L10,"")) -> 13.38 | N10: 14.45 | O10: 5.14 | P10: 5.97 | Q10: =IF(COUNT(O10,P10)=0,"",IFERROR(O10*1000/P10*1000,"")) -> 860971.52 | S10: =IF(COUNT(O10,P10)=0,"",IFERROR(O10*P10,"")) -> 30.6858 | T10: 72.8 | U10: =IF(COUNT(T10)=0,"",IFERROR(COS(T10/180*PI()),"")) -> 0.29570805 | V10: =IF(COUNT(S10,T10)=0,"",IFERROR(S10*COS(T10/360*2*3.14),"")) -> 9.0929182 | W10: =IF(COUNT(V10,M10)=0,"",IFERROR(1-V10/M10,"")) -> 0.3204097 | Z10: =IFERROR(IF(OR(V10="",X10="",X10=0),"",(V10-X10)/X10*100),"") | AA10: =IF(COUNT(AD10,AE10,AF10,AG10,AH10,AI10,AJ10,AK10,AL10,AC10)=0,"",IFERROR(SQRT(AD10^2+AE10^2+AF10^2+AG10^2+AH10^2+AI10^2+AJ10^2+AK10^2+AL10^2)/AC10,"")) -> 0.082528204 | AC10: 4855 | AD10: 312 | AE10: 210 | AF10: 89 | AG10: 82 | AH10: 45 | AI10: 36 | AJ10: 25 | AK10: 19 | AL10: 12 | AM10: 52
A11: BLOCK 1 | B11: 7 | C11: SQUARE | E11: 20 | G11: 100 | H11: 7 | I11: 6.68 | J11: 778 | K11: =IF(COUNT(J11,I11)=0,"",IFERROR(J11/1000/I11,"")) -> 0.11646707 | L11: 2.29 | M11: =IF(COUNT(H11,L11)=0,"",IFERROR(H11*L11,"")) -> 16.03 | N11: 16.44 | O11: 5.91 | P11: 6.97 | Q11: =IF(COUNT(O11,P11)=0,"",IFERROR(O11*1000/P11*1000,"")) -> 847919.66 | S11: =IF(COUNT(O11,P11)=0,"",IFERROR(O11*P11,"")) -> 41.1927 | T11: 72.5 | U11: =IF(COUNT(T11)=0,"",IFERROR(COS(T11/180*PI()),"")) -> 0.3007058 | V11: =IF(COUNT(S11,T11)=0,"",IFERROR(S11*COS(T11/360*2*3.14),"")) -> 12.412083 | W11: =IF(COUNT(V11,M11)=0,"",IFERROR(1-V11/M11,"")) -> 0.22569665 | Z11: =IFERROR(IF(OR(V11="",X11="",X11=0),"",(V11-X11)/X11*100),"") | AA11: =IF(COUNT(AD11,AE11,AF11,AG11,AH11,AI11,AJ11,AK11,AL11,AC11)=0,"",IFERROR(SQRT(AD11^2+AE11^2+AF11^2+AG11^2+AH11^2+AI11^2+AJ11^2+AK11^2+AL11^2)/AC11,"")) -> 0.091291697 | AC11: 5558 | AD11: 356 | AE11: 311 | AF11: 134 | AG11: 107 | AH11: 49 | AI11: 35 | AJ11: 22 | AK11: 19 | AL11: 11 | AM11: 52
A12: BLOCK 1 | B12: 8 | C12: SQUARE | E12: 20 | G12: 100 | H12: 8 | I12: 7.67 | J12: 877 | K12: =IF(COUNT(J12,I12)=0,"",IFERROR(J12/1000/I12,"")) -> 0.11434159 | L12: 2.4 | M12: =IF(COUNT(H12,L12)=0,"",IFERROR(H12*L12,"")) -> 19.2 | N12: 19.22 | O12: 6.86 | P12: 8.27 | Q12: =IF(COUNT(O12,P12)=0,"",IFERROR(O12*1000/P12*1000,"")) -> 829504.23 | S12: =IF(COUNT(O12,P12)=0,"",IFERROR(O12*P12,"")) -> 56.7322 | T12: 72.2 | U12: =IF(COUNT(T12)=0,"",IFERROR(COS(T12/180*PI()),"")) -> 0.3056953 | V12: =IF(COUNT(S12,T12)=0,"",IFERROR(S12*COS(T12/360*2*3.14),"")) -> 17.377271 | W12: =IF(COUNT(V12,M12)=0,"",IFERROR(1-V12/M12,"")) -> 0.094933803 | Z12: =IFERROR(IF(OR(V12="",X12="",X12=0),"",(V12-X12)/X12*100),"") | AA12: =IF(COUNT(AD12,AE12,AF12,AG12,AH12,AI12,AJ12,AK12,AL12,AC12)=0,"",IFERROR(SQRT(AD12^2+AE12^2+AF12^2+AG12^2+AH12^2+AI12^2+AJ12^2+AK12^2+AL12^2)/AC12,"")) -> 0.09463479 | AC12: 6504 | AD12: 409 | AE12: 358 | AF12: 240 | AG12: 136 | AH12: 60 | AI12: 48 | AJ12: 26 | AK12: 23 | AL12: 14 | AM12: 52
A13: BLOCK 1 | B13: 9 | C13: SQUARE | E13: 20 | G13: 100 | H13: 9 | I13: 8.74 | J13: 937 | K13: =IF(COUNT(J13,I13)=0,"",IFERROR(J13/1000/I13,"")) -> 0.10720824 | L13: 2.58 | M13: =IF(COUNT(H13,L13)=0,"",IFERROR(H13*L13,"")) -> 23.22 | N13: 22.54 | O13: 8.04 | P13: 9.78 | Q13: =IF(COUNT(O13,P13)=0,"",IFERROR(O13*1000/P13*1000,"")) -> 822085.89 | S13: =IF(COUNT(O13,P13)=0,"",IFERROR(O13*P13,"")) -> 78.6312 | T13: 73.1 | U13: =IF(COUNT(T13)=0,"",IFERROR(COS(T13/180*PI()),"")) -> 0.29070219 | V13: =IF(COUNT(S13,T13)=0,"",IFERROR(S13*COS(T13/360*2*3.14),"")) -> 22.906919 | W13: =IF(COUNT(V13,M13)=0,"",IFERROR(1-V13/M13,"")) -> 0.013483231 | Z13: =IFERROR(IF(OR(V13="",X13="",X13=0),"",(V13-X13)/X13*100),"") | AA13: =IF(COUNT(AD13,AE13,AF13,AG13,AH13,AI13,AJ13,AK13,AL13,AC13)=0,"",IFERROR(SQRT(AD13^2+AE13^2+AF13^2+AG13^2+AH13^2+AI13^2+AJ13^2+AK13^2+AL13^2)/AC13,"")) -> 0.088795344 | AC13: 7596 | AD13: 384 | AE13: 377 | AF13: 359 | AG13: 167 | AH13: 70 | AI13: 50 | AJ13: 24 | AK13: 22 | AL13: 11 | AM13: 52
A14: BLOCK 1 | B14: 10 | C14: SQUARE | E14: 20 | G14: 100 | H14: 10 | I14: 9.78 | J14: 1017 | K14: =IF(COUNT(J14,I14)=0,"",IFERROR(J14/1000/I14,"")) -> 0.10398773 | L14: 2.88 | M14: =IF(COUNT(H14,L14)=0,"",IFERROR(H14*L14,"")) -> 28.8 | N14: 25.65 | O14: 9.15 | P14: 11.37 | Q14: =IF(COUNT(O14,P14)=0,"",IFERROR(O14*1000/P14*1000,"")) -> 804749.34 | S14: =IF(COUNT(O14,P14)=0,"",IFERROR(O14*P14,"")) -> 104.0355 | T14: 73.9 | U14: =IF(COUNT(T14)=0,"",IFERROR(COS(T14/180*PI()),"")) -> 0.27731465 | V14: =IF(COUNT(S14,T14)=0,"",IFERROR(S14*COS(T14/360*2*3.14),"")) -> 28.91592 | W14: =IF(COUNT(V14,M14)=0,"",IFERROR(1-V14/M14,"")) -> -0.0040250134 | Z14: =IFERROR(IF(OR(V14="",X14="",X14=0),"",(V14-X14)/X14*100),"") | AA14: =IF(COUNT(AD14,AE14,AF14,AG14,AH14,AI14,AJ14,AK14,AL14,AC14)=0,"",IFERROR(SQRT(AD14^2+AE14^2+AF14^2+AG14^2+AH14^2+AI14^2+AJ14^2+AK14^2+AL14^2)/AC14,"")) -> 0.083679384 | AC14: 8582 | AD14: 451 | AE14: 393 | AF14: 335 | AG14: 188 | AH14: 78 | AI14: 54 | AJ14: 24 | AK14: 23 | AL14: 14 | AM14: 52
A15: BLOCK 2 — Probe load (open circuit) · V-sweep · 10 kHz · DC 100% · SQUARE — MOSFET failure at step 11
A16: BLOCK 2 | B16: 1 | C16: SQUARE | E16: 10 | G16: 100 | H16: 1 | I16: 0.995 | J16: 155 | K16: =IF(COUNT(J16,I16)=0,"",IFERROR(J16/1000/I16,"")) -> 0.15577889 | L16: 0.12 | M16: =IF(COUNT(H16,L16)=0,"",IFERROR(H16*L16,"")) -> 0.12 | N16: 2.08 | O16: 0.695 | P16: 0.417 | Q16: =IF(COUNT(O16,P16)=0,"",IFERROR(O16*1000/P16*1000,"")) -> 1666666.7 | S16: =IF(COUNT(O16,P16)=0,"",IFERROR(O16*P16,"")) -> 0.289815 | T16: 73.5 | U16: =IF(COUNT(T16)=0,"",IFERROR(COS(T16/180*PI()),"")) -> 0.28401534 | V16: =IF(COUNT(S16,T16)=0,"",IFERROR(S16*COS(T16/360*2*3.14),"")) -> 0.082492605 | W16: =IF(COUNT(V16,M16)=0,"",IFERROR(1-V16/M16,"")) -> 0.31256163 | Z16: =IFERROR(IF(OR(V16="",X16="",X16=0),"",(V16-X16)/X16*100),"") | AA16: =IF(COUNT(AD16,AE16,AF16,AG16,AH16,AI16,AJ16,AK16,AL16,AC16)=0,"",IFERROR(SQRT(AD16^2+AE16^2+AF16^2+AG16^2+AH16^2+AI16^2+AJ16^2+AK16^2+AL16^2)/AC16,"")) -> 0.33204857 | AC16: 657 | AD16: 191 | AE16: 100 | AF16: 26 | AG16: 13 | AH16: 11 | AI16: 9 | AJ16: 8 | AM16: 25 | AR16: Distorted sine
A17: BLOCK 2 | B17: 2 | C17: SQUARE | E17: 10 | G17: 100 | H17: 2 | I17: 1.999 | J17: 195 | K17: =IF(COUNT(J17,I17)=0,"",IFERROR(J17/1000/I17,"")) -> 0.097548774 | L17: 0.17 | M17: =IF(COUNT(H17,L17)=0,"",IFERROR(H17*L17,"")) -> 0.34 | N17: 3.81 | O17: 1.31 | P17: 0.575 | Q17: =IF(COUNT(O17,P17)=0,"",IFERROR(O17*1000/P17*1000,"")) -> 2278260.9 | S17: =IF(COUNT(O17,P17)=0,"",IFERROR(O17*P17,"")) -> 0.75325 | T17: 67.9 | U17: =IF(COUNT(T17)=0,"",IFERROR(COS(T17/180*PI()),"")) -> 0.37622426 | V17: =IF(COUNT(S17,T17)=0,"",IFERROR(S17*COS(T17/360*2*3.14),"")) -> 0.28381017 | W17: =IF(COUNT(V17,M17)=0,"",IFERROR(1-V17/M17,"")) -> 0.16526421 | Z17: =IFERROR(IF(OR(V17="",X17="",X17=0),"",(V17-X17)/X17*100),"") | AA17: =IF(COUNT(AD17,AE17,AF17,AG17,AH17,AI17,AJ17,AK17,AL17,AC17)=0,"",IFERROR(SQRT(AD17^2+AE17^2+AF17^2+AG17^2+AH17^2+AI17^2+AJ17^2+AK17^2+AL17^2)/AC17,"")) -> 0.19774221 | AC17: 1288 | AD17: 226 | AE17: 100 | AF17: 43 | AG17: 37 | AH17: 16 | AI17: 12 | AJ17: 10 | AK17: 7 | AL17: 5 | AM17: 25
A18: BLOCK 2 | B18: 3 | C18: SQUARE | E18: 10 | G18: 100 | H18: 3 | I18: 2.98 | J18: 203 | K18: =IF(COUNT(J18,I18)=0,"",IFERROR(J18/1000/I18,"")) -> 0.068120805 | L18: 0.27 | M18: =IF(COUNT(H18,L18)=0,"",IFERROR(H18*L18,"")) -> 0.81 | N18: 5.36 | O18: 1.909 | P18: 0.696 | Q18: =IF(COUNT(O18,P18)=0,"",IFERROR(O18*1000/P18*1000,"")) -> 2742816.1 | S18: =IF(COUNT(O18,P18)=0,"",IFERROR(O18*P18,"")) -> 1.328664 | T18: 61.6 | U18: =IF(COUNT(T18)=0,"",IFERROR(COS(T18/180*PI()),"")) -> 0.47562421 | V18: =IF(COUNT(S18,T18)=0,"",IFERROR(S18*COS(T18/360*2*3.14),"")) -> 0.63258169 | W18: =IF(COUNT(V18,M18)=0,"",IFERROR(1-V18/M18,"")) -> 0.21903495 | Z18: =IFERROR(IF(OR(V18="",X18="",X18=0),"",(V18-X18)/X18*100),"") | AA18: =IF(COUNT(AD18,AE18,AF18,AG18,AH18,AI18,AJ18,AK18,AL18,AC18)=0,"",IFERROR(SQRT(AD18^2+AE18^2+AF18^2+AG18^2+AH18^2+AI18^2+AJ18^2+AK18^2+AL18^2)/AC18,"")) -> 0.12343829 | AC18: 1888 | AD18: 192 | AE18: 100 | AF18: 67 | AG18: 47 | AH18: 21 | AI18: 12 | AJ18: 9 | AK18: 7 | AL18: 6 | AM18: 25
A19: BLOCK 2 | B19: 4 | C19: SQUARE | E19: 10 | G19: 100 | H19: 4 | I19: 3.989 | J19: 203 | K19: =IF(COUNT(J19,I19)=0,"",IFERROR(J19/1000/I19,"")) -> 0.050889947 | L19: 0.33 | M19: =IF(COUNT(H19,L19)=0,"",IFERROR(H19*L19,"")) -> 1.32 | N19: 6.98 | O19: 2.509 | P19: 0.833 | Q19: =IF(COUNT(O19,P19)=0,"",IFERROR(O19*1000/P19*1000,"")) -> 3012004.8 | S19: =IF(COUNT(O19,P19)=0,"",IFERROR(O19*P19,"")) -> 2.089997 | T19: 62.6 | U19: =IF(COUNT(T19)=0,"",IFERROR(COS(T19/180*PI()),"")) -> 0.46019978 | V19: =IF(COUNT(S19,T19)=0,"",IFERROR(S19*COS(T19/360*2*3.14),"")) -> 0.96284378 | W19: =IF(COUNT(V19,M19)=0,"",IFERROR(1-V19/M19,"")) -> 0.27057289 | Z19: =IFERROR(IF(OR(V19="",X19="",X19=0),"",(V19-X19)/X19*100),"") | AA19: =IF(COUNT(AD19,AE19,AF19,AG19,AH19,AI19,AJ19,AK19,AL19,AC19)=0,"",IFERROR(SQRT(AD19^2+AE19^2+AF19^2+AG19^2+AH19^2+AI19^2+AJ19^2+AK19^2+AL19^2)/AC19,"")) -> 0.084930095 | AC19: 2491 | AD19: 154 | AE19: 104 | AF19: 74 | AG19: 59 | AH19: 29 | AI19: 16 | AJ19: 10 | AK19: 6 | AL19: 6 | AM19: 26 | AR19: Sine for the voltage, two peaks for the current
A20: BLOCK 2 | B20: 5 | C20: SQUARE | E20: 10 | G20: 100 | H20: 5 | I20: 4.98 | J20: 223 | K20: =IF(COUNT(J20,I20)=0,"",IFERROR(J20/1000/I20,"")) -> 0.044779116 | L20: 0.43 | M20: =IF(COUNT(H20,L20)=0,"",IFERROR(H20*L20,"")) -> 2.15 | N20: 8.53 | O20: 3.09 | P20: 1.01 | Q20: =IF(COUNT(O20,P20)=0,"",IFERROR(O20*1000/P20*1000,"")) -> 3059405.9 | S20: =IF(COUNT(O20,P20)=0,"",IFERROR(O20*P20,"")) -> 3.1209 | T20: 57.8 | U20: =IF(COUNT(T20)=0,"",IFERROR(COS(T20/180*PI()),"")) -> 0.53287628 | V20: =IF(COUNT(S20,T20)=0,"",IFERROR(S20*COS(T20/360*2*3.14),"")) -> 1.664404 | W20: =IF(COUNT(V20,M20)=0,"",IFERROR(1-V20/M20,"")) -> 0.22585863 | Z20: =IFERROR(IF(OR(V20="",X20="",X20=0),"",(V20-X20)/X20*100),"") | AA20: =IF(COUNT(AD20,AE20,AF20,AG20,AH20,AI20,AJ20,AK20,AL20,AC20)=0,"",IFERROR(SQRT(AD20^2+AE20^2+AF20^2+AG20^2+AH20^2+AI20^2+AJ20^2+AK20^2+AL20^2)/AC20,"")) -> 0.089989993 | AC20: 3069 | AD20: 197 | AE20: 154 | AF20: 82 | AG20: 71 | AH20: 36 | AI20: 20 | AJ20: 12 | AK20: 9 | AL20: 8 | AM20: 28 | AR20: Same
A21: BLOCK 2 | B21: 6 | C21: SQUARE | E21: 10 | G21: 100 | H21: 6 | I21: 5.99 | J21: 303 | K21: =IF(COUNT(J21,I21)=0,"",IFERROR(J21/1000/I21,"")) -> 0.050584307 | L21: 0.52 | M21: =IF(COUNT(H21,L21)=0,"",IFERROR(H21*L21,"")) -> 3.12 | N21: 10.38 | O21: 3.779 | P21: 1.207 | Q21: =IF(COUNT(O21,P21)=0,"",IFERROR(O21*1000/P21*1000,"")) -> 3130903.1 | S21: =IF(COUNT(O21,P21)=0,"",IFERROR(O21*P21,"")) -> 4.561253 | T21: 58.74 | U21: =IF(COUNT(T21)=0,"",IFERROR(COS(T21/180*PI()),"")) -> 0.51892246 | V21: =IF(COUNT(S21,T21)=0,"",IFERROR(S21*COS(T21/360*2*3.14),"")) -> 2.3689628 | W21: =IF(COUNT(V21,M21)=0,"",IFERROR(1-V21/M21,"")) -> 0.24071705 | Z21: =IFERROR(IF(OR(V21="",X21="",X21=0),"",(V21-X21)/X21*100),"") | AA21: =IF(COUNT(AD21,AE21,AF21,AG21,AH21,AI21,AJ21,AK21,AL21,AC21)=0,"",IFERROR(SQRT(AD21^2+AE21^2+AF21^2+AG21^2+AH21^2+AI21^2+AJ21^2+AK21^2+AL21^2)/AC21,"")) -> 0.17419321 | AC21: 3722 | AD21: 603 | AE21: 187 | AF21: 102 | AG21: 91 | AH21: 46 | AI21: 23 | AJ21: 15 | AK21: 11 | AL21: 10 | AM21: 29
A22: BLOCK 2 | B22: 7 | C22: SQUARE | E22: 10 | G22: 100 | H22: 7 | I22: 6.98 | J22: 343 | K22: =IF(COUNT(J22,I22)=0,"",IFERROR(J22/1000/I22,"")) -> 0.049140401 | L22: 0.59 | M22: =IF(COUNT(H22,L22)=0,"",IFERROR(H22*L22,"")) -> 4.13 | N22: 12.18 | O22: 4.42 | P22: 1.461 | Q22: =IF(COUNT(O22,P22)=0,"",IFERROR(O22*1000/P22*1000,"")) -> 3025325.1 | S22: =IF(COUNT(O22,P22)=0,"",IFERROR(O22*P22,"")) -> 6.45762 | T22: 58.78 | U22: =IF(COUNT(T22)=0,"",IFERROR(COS(T22/180*PI()),"")) -> 0.51832556 | V22: =IF(COUNT(S22,T22)=0,"",IFERROR(S22*COS(T22/360*2*3.14),"")) -> 3.3500212 | W22: =IF(COUNT(V22,M22)=0,"",IFERROR(1-V22/M22,"")) -> 0.18885685 | Z22: =IFERROR(IF(OR(V22="",X22="",X22=0),"",(V22-X22)/X22*100),"") | AA22: =IF(COUNT(AD22,AE22,AF22,AG22,AH22,AI22,AJ22,AK22,AL22,AC22)=0,"",IFERROR(SQRT(AD22^2+AE22^2+AF22^2+AG22^2+AH22^2+AI22^2+AJ22^2+AK22^2+AL22^2)/AC22,"")) -> 0.16510592 | AC22: 4387 | AD22: 631 | AE22: 295 | AF22: 141 | AG22: 122 | AH22: 50 | AI22: 34 | AJ22: 26 | AK22: 16 | AL22: 10 | AM22: 32
A23: BLOCK 2 | B23: 8 | C23: SQUARE | E23: 10 | G23: 100 | H23: 8 | I23: 7.99 | J23: 391 | K23: =IF(COUNT(J23,I23)=0,"",IFERROR(J23/1000/I23,"")) -> 0.04893617 | L23: 0.68 | M23: =IF(COUNT(H23,L23)=0,"",IFERROR(H23*L23,"")) -> 5.44 | N23: 14.57 | O23: 5.211 | P23: 1.916 | Q23: =IF(COUNT(O23,P23)=0,"",IFERROR(O23*1000/P23*1000,"")) -> 2719728.6 | S23: =IF(COUNT(O23,P23)=0,"",IFERROR(O23*P23,"")) -> 9.984276 | T23: 62.2 | U23: =IF(COUNT(T23)=0,"",IFERROR(COS(T23/180*PI()),"")) -> 0.46638664 | V23: =IF(COUNT(S23,T23)=0,"",IFERROR(S23*COS(T23/360*2*3.14),"")) -> 4.6613929 | W23: =IF(COUNT(V23,M23)=0,"",IFERROR(1-V23/M23,"")) -> 0.14312631 | Z23: =IFERROR(IF(OR(V23="",X23="",X23=0),"",(V23-X23)/X23*100),"") | AA23: =IF(COUNT(AD23,AE23,AF23,AG23,AH23,AI23,AJ23,AK23,AL23,AC23)=0,"",IFERROR(SQRT(AD23^2+AE23^2+AF23^2+AG23^2+AH23^2+AI23^2+AJ23^2+AK23^2+AL23^2)/AC23,"")) -> 0.17163544 | AC23: 5123 | AD23: 636 | AE23: 548 | AF23: 209 | AG23: 132 | AH23: 58 | AI23: 47 | AJ23: 34 | AK23: 17 | AL23: 15 | AM23: 35
A24: BLOCK 2 | B24: 9 | C24: SQUARE | E24: 10 | G24: 100 | H24: 9 | I24: 8.98 | J24: 510 | K24: =IF(COUNT(J24,I24)=0,"",IFERROR(J24/1000/I24,"")) -> 0.056792873 | L24: 0.7 | M24: =IF(COUNT(H24,L24)=0,"",IFERROR(H24*L24,"")) -> 6.3 | N24: 16.53 | O24: 6.045 | P24: 2.332 | Q24: =IF(COUNT(O24,P24)=0,"",IFERROR(O24*1000/P24*1000,"")) -> 2592195.5 | S24: =IF(COUNT(O24,P24)=0,"",IFERROR(O24*P24,"")) -> 14.09694 | T24: 65.4 | U24: =IF(COUNT(T24)=0,"",IFERROR(COS(T24/180*PI()),"")) -> 0.41628079 | V24: =IF(COUNT(S24,T24)=0,"",IFERROR(S24*COS(T24/360*2*3.14),"")) -> 5.8757014 | W24: =IF(COUNT(V24,M24)=0,"",IFERROR(1-V24/M24,"")) -> 0.06734899 | Z24: =IFERROR(IF(OR(V24="",X24="",X24=0),"",(V24-X24)/X24*100),"") | AA24: =IF(COUNT(AD24,AE24,AF24,AG24,AH24,AI24,AJ24,AK24,AL24,AC24)=0,"",IFERROR(SQRT(AD24^2+AE24^2+AF24^2+AG24^2+AH24^2+AI24^2+AJ24^2+AK24^2+AL24^2)/AC24,"")) -> 0.27507932 | AC24: 5845 | AD24: 1325 | AE24: 860 | AF24: 265 | AG24: 91 | AH24: 70 | AI24: 62 | AJ24: 35 | AK24: 31 | AL24: 22 | AM24: 36
A25: BLOCK 2 | B25: 10 | C25: SQUARE | E25: 10 | G25: 100 | H25: 10 | I25: 9.98 | J25: 303 | K25: =IF(COUNT(J25,I25)=0,"",IFERROR(J25/1000/I25,"")) -> 0.030360721 | L25: 0.51 | M25: =IF(COUNT(H25,L25)=0,"",IFERROR(H25*L25,"")) -> 5.1 | N25: 17.71 | O25: 6.663 | P25: 2.141 | Q25: =IF(COUNT(O25,P25)=0,"",IFERROR(O25*1000/P25*1000,"")) -> 3112097.2 | S25: =IF(COUNT(O25,P25)=0,"",IFERROR(O25*P25,"")) -> 14.265483 | T25: 66.36 | U25: =IF(COUNT(T25)=0,"",IFERROR(COS(T25/180*PI()),"")) -> 0.40098868 | V25: =IF(COUNT(S25,T25)=0,"",IFERROR(S25*COS(T25/360*2*3.14),"")) -> 5.7279694 | W25: =IF(COUNT(V25,M25)=0,"",IFERROR(1-V25/M25,"")) -> -0.12313125 | Z25: =IFERROR(IF(OR(V25="",X25="",X25=0),"",(V25-X25)/X25*100),"") | AA25: =IF(COUNT(AD25,AE25,AF25,AG25,AH25,AI25,AJ25,AK25,AL25,AC25)=0,"",IFERROR(SQRT(AD25^2+AE25^2+AF25^2+AG25^2+AH25^2+AI25^2+AJ25^2+AK25^2+AL25^2)/AC25,"")) -> 0.25786001 | AC25: 6437 | AD25: 1333 | AE25: 930 | AF25: 290 | AG25: 104 | AH25: 95 | AI25: 65 | AJ25: 55 | AK25: 43 | AL25: 16 | AM25: 31
A26: BLOCK 2 | B26: 11 | C26: SQUARE | E26: 10 | G26: 100 | H26: 11 | K26: =IF(COUNT(J26,I26)=0,"",IFERROR(J26/1000/I26,"")) | M26: =IF(COUNT(H26,L26)=0,"",IFERROR(H26*L26,"")) -> 0 | Q26: =IF(COUNT(O26,P26)=0,"",IFERROR(O26*1000/P26*1000,"")) | S26: =IF(COUNT(O26,P26)=0,"",IFERROR(O26*P26,"")) | U26: =IF(COUNT(T26)=0,"",IFERROR(COS(T26/180*PI()),"")) | V26: =IF(COUNT(S26,T26)=0,"",IFERROR(S26*COS(T26/360*2*3.14),"")) | W26: =IF(COUNT(V26,M26)=0,"",IFERROR(1-V26/M26,"")) | Z26: =IFERROR(IF(OR(V26="",X26="",X26=0),"",(V26-X26)/X26*100),"") | AA26: =IF(COUNT(AD26,AE26,AF26,AG26,AH26,AI26,AJ26,AK26,AL26,AC26)=0,"",IFERROR(SQRT(AD26^2+AE26^2+AF26^2+AG26^2+AH26^2+AI26^2+AJ26^2+AK26^2+AL26^2)/AC26,"")) | AR26: MOSFET failure: the generator stopped working correctly because a MOSFET failed; it was replaced (desoldered and resoldered). The failure is most likely due to excessive heating; compared with the other V-sweeps in this configuration, the recorded temperature was abnormally low.
A27: BLOCK 3 — Probe load (open circuit) · V-sweep · 15 kHz · DC 100% · SQUARE (10 steps, MOSFET replaced) — several steps show a negative loss fraction (efficiency > 100 %), consistent with a residual phase-shift bias between the probes
A28: BLOCK 3 | B28: 1 | C28: SQUARE | E28: 15 | G28: 100 | H28: 1 | J28: 71 | K28: =IF(COUNT(J28,I28)=0,"",IFERROR(J28/1000/I28,"")) | L28: 0.13 | M28: =IF(COUNT(H28,L28)=0,"",IFERROR(H28*L28,"")) -> 0.13 | N28: 1.89 | O28: 0.706 | P28: 0.448 | Q28: =IF(COUNT(O28,P28)=0,"",IFERROR(O28*1000/P28*1000,"")) -> 1575892.9 | S28: =IF(COUNT(O28,P28)=0,"",IFERROR(O28*P28,"")) -> 0.316288 | T28: 78.5 | U28: =IF(COUNT(T28)=0,"",IFERROR(COS(T28/180*PI()),"")) -> 0.19936793 | V28: =IF(COUNT(S28,T28)=0,"",IFERROR(S28*COS(T28/360*2*3.14),"")) -> 0.063272945 | W28: =IF(COUNT(V28,M28)=0,"",IFERROR(1-V28/M28,"")) -> 0.51328504 | X28: 0.062 | Y28: 0.196 | Z28: =IFERROR(IF(OR(V28="",X28="",X28=0),"",(V28-X28)/X28*100),"") -> 2.0531374 | AA28: =IF(COUNT(AD28,AE28,AF28,AG28,AH28,AI28,AJ28,AK28,AL28,AC28)=0,"",IFERROR(SQRT(AD28^2+AE28^2+AF28^2+AG28^2+AH28^2+AI28^2+AJ28^2+AK28^2+AL28^2)/AC28,"")) -> 0.31048968 | AC28: 675 | AD28: 203 | AE28: 45 | AF28: 20 | AG28: 13 | AH28: 11 | AM28: 26
A29: BLOCK 3 | B29: 2 | C29: SQUARE | E29: 15 | G29: 100 | H29: 2 | I29: 2 | J29: 105 | K29: =IF(COUNT(J29,I29)=0,"",IFERROR(J29/1000/I29,"")) -> 0.0525 | L29: 0.36 | M29: =IF(COUNT(H29,L29)=0,"",IFERROR(H29*L29,"")) -> 0.72 | N29: 3.55 | O29: 1.21 | P29: 0.729 | Q29: =IF(COUNT(O29,P29)=0,"",IFERROR(O29*1000/P29*1000,"")) -> 1659808 | S29: =IF(COUNT(O29,P29)=0,"",IFERROR(O29*P29,"")) -> 0.88209 | T29: 61 | U29: =IF(COUNT(T29)=0,"",IFERROR(COS(T29/180*PI()),"")) -> 0.48480962 | V29: =IF(COUNT(S29,T29)=0,"",IFERROR(S29*COS(T29/360*2*3.14),"")) -> 0.42806206 | W29: =IF(COUNT(V29,M29)=0,"",IFERROR(1-V29/M29,"")) -> 0.40546937 | X29: 0.405 | Y29: 0.495 | Z29: =IFERROR(IF(OR(V29="",X29="",X29=0),"",(V29-X29)/X29*100),"") -> 5.6943347 | AA29: =IF(COUNT(AD29,AE29,AF29,AG29,AH29,AI29,AJ29,AK29,AL29,AC29)=0,"",IFERROR(SQRT(AD29^2+AE29^2+AF29^2+AG29^2+AH29^2+AI29^2+AJ29^2+AK29^2+AL29^2)/AC29,"")) -> 0.17209462 | AC29: 1239 | AD29: 208 | AE29: 35 | AF29: 23 | AG29: 16 | AH29: 9 | AI29: 7 | AJ29: 6 | AK29: 5 | AM29: 28
A30: BLOCK 3 | B30: 3 | C30: SQUARE | E30: 15 | G30: 100 | H30: 3 | I30: 3 | J30: 175 | K30: =IF(COUNT(J30,I30)=0,"",IFERROR(J30/1000/I30,"")) -> 0.058333333 | L30: 0.56 | M30: =IF(COUNT(H30,L30)=0,"",IFERROR(H30*L30,"")) -> 1.68 | N30: 5.13 | O30: 1.75 | P30: 0.977 | Q30: =IF(COUNT(O30,P30)=0,"",IFERROR(O30*1000/P30*1000,"")) -> 1791197.5 | S30: =IF(COUNT(O30,P30)=0,"",IFERROR(O30*P30,"")) -> 1.70975 | T30: 58.6 | U30: =IF(COUNT(T30)=0,"",IFERROR(COS(T30/180*PI()),"")) -> 0.52100963 | V30: =IF(COUNT(S30,T30)=0,"",IFERROR(S30*COS(T30/360*2*3.14),"")) -> 0.89155277 | W30: =IF(COUNT(V30,M30)=0,"",IFERROR(1-V30/M30,"")) -> 0.46931383 | X30: 0.917 | Y30: 0.522 | Z30: =IFERROR(IF(OR(V30="",X30="",X30=0),"",(V30-X30)/X30*100),"") -> -2.7750522 | AA30: =IF(COUNT(AD30,AE30,AF30,AG30,AH30,AI30,AJ30,AK30,AL30,AC30)=0,"",IFERROR(SQRT(AD30^2+AE30^2+AF30^2+AG30^2+AH30^2+AI30^2+AJ30^2+AK30^2+AL30^2)/AC30,"")) -> 0.12831043 | AC30: 1756 | AD30: 209 | AE30: 74 | AF30: 26 | AG30: 24 | AH30: 12 | AI30: 10 | AJ30: 8 | AK30: 7 | AM30: 33
A31: BLOCK 3 | B31: 4 | C31: SQUARE | E31: 15 | G31: 100 | H31: 4 | I31: 4 | J31: 180 | K31: =IF(COUNT(J31,I31)=0,"",IFERROR(J31/1000/I31,"")) -> 0.045 | L31: 0.77 | M31: =IF(COUNT(H31,L31)=0,"",IFERROR(H31*L31,"")) -> 3.08 | N31: 7.03 | O31: 2.48 | P31: 1.49 | Q31: =IF(COUNT(O31,P31)=0,"",IFERROR(O31*1000/P31*1000,"")) -> 1664429.5 | S31: =IF(COUNT(O31,P31)=0,"",IFERROR(O31*P31,"")) -> 3.6952 | T31: 61.7 | U31: =IF(COUNT(T31)=0,"",IFERROR(COS(T31/180*PI()),"")) -> 0.47408821 | V31: =IF(COUNT(S31,T31)=0,"",IFERROR(S31*COS(T31/360*2*3.14),"")) -> 1.7536267 | W31: =IF(COUNT(V31,M31)=0,"",IFERROR(1-V31/M31,"")) -> 0.43064069 | X31: 1.755 | Y31: 0.475 | Z31: =IFERROR(IF(OR(V31="",X31="",X31=0),"",(V31-X31)/X31*100),"") -> -0.078251749 | AA31: =IF(COUNT(AD31,AE31,AF31,AG31,AH31,AI31,AJ31,AK31,AL31,AC31)=0,"",IFERROR(SQRT(AD31^2+AE31^2+AF31^2+AG31^2+AH31^2+AI31^2+AJ31^2+AK31^2+AL31^2)/AC31,"")) -> 0.093275712 | AC31: 2204 | AD31: 177 | AE31: 91 | AF31: 33 | AG31: 28 | AH31: 19 | AI31: 15 | AJ31: 9 | AK31: 8 | AL31: 7 | AM31: 39
A32: BLOCK 3 | B32: 5 | C32: SQUARE | E32: 15 | G32: 100 | H32: 5 | I32: 5 | J32: 260 | K32: =IF(COUNT(J32,I32)=0,"",IFERROR(J32/1000/I32,"")) -> 0.052 | L32: 0.96 | M32: =IF(COUNT(H32,L32)=0,"",IFERROR(H32*L32,"")) -> 4.8 | N32: 9.16 | O32: 3.225 | P32: 1.93 | Q32: =IF(COUNT(O32,P32)=0,"",IFERROR(O32*1000/P32*1000,"")) -> 1670984.5 | S32: =IF(COUNT(O32,P32)=0,"",IFERROR(O32*P32,"")) -> 6.22425 | T32: 62.5 | U32: =IF(COUNT(T32)=0,"",IFERROR(COS(T32/180*PI()),"")) -> 0.46174861 | V32: =IF(COUNT(S32,T32)=0,"",IFERROR(S32*COS(T32/360*2*3.14),"")) -> 2.8770915 | W32: =IF(COUNT(V32,M32)=0,"",IFERROR(1-V32/M32,"")) -> 0.40060594 | X32: 2.902 | Y32: 0.466 | Z32: =IFERROR(IF(OR(V32="",X32="",X32=0),"",(V32-X32)/X32*100),"") -> -0.8583221 | AA32: =IF(COUNT(AD32,AE32,AF32,AG32,AH32,AI32,AJ32,AK32,AL32,AC32)=0,"",IFERROR(SQRT(AD32^2+AE32^2+AF32^2+AG32^2+AH32^2+AI32^2+AJ32^2+AK32^2+AL32^2)/AC32,"")) -> 0.063750984 | AC32: 3212 | AD32: 179 | AE32: 81 | AF32: 35 | AG32: 31 | AH32: 25 | AI32: 14 | AJ32: 11 | AK32: 10 | AL32: 10 | AM32: 46
A33: BLOCK 3 | B33: 6 | C33: SQUARE | E33: 15 | G33: 100 | H33: 6 | I33: 6 | J33: 360 | K33: =IF(COUNT(J33,I33)=0,"",IFERROR(J33/1000/I33,"")) -> 0.06 | L33: 1.06 | M33: =IF(COUNT(H33,L33)=0,"",IFERROR(H33*L33,"")) -> 6.36 | N33: 11.29 | O33: 4.001 | P33: 2.36 | Q33: =IF(COUNT(O33,P33)=0,"",IFERROR(O33*1000/P33*1000,"")) -> 1695339 | S33: =IF(COUNT(O33,P33)=0,"",IFERROR(O33*P33,"")) -> 9.44236 | T33: 60.9 | U33: =IF(COUNT(T33)=0,"",IFERROR(COS(T33/180*PI()),"")) -> 0.48633538 | V33: =IF(COUNT(S33,T33)=0,"",IFERROR(S33*COS(T33/360*2*3.14),"")) -> 4.5965988 | W33: =IF(COUNT(V33,M33)=0,"",IFERROR(1-V33/M33,"")) -> 0.27726434 | X33: 4.812 | Y33: 0.503 | Z33: =IFERROR(IF(OR(V33="",X33="",X33=0),"",(V33-X33)/X33*100),"") -> -4.4763337 | AA33: =IF(COUNT(AD33,AE33,AF33,AG33,AH33,AI33,AJ33,AK33,AL33,AC33)=0,"",IFERROR(SQRT(AD33^2+AE33^2+AF33^2+AG33^2+AH33^2+AI33^2+AJ33^2+AK33^2+AL33^2)/AC33,"")) -> 0.048302922 | AC33: 4016 | AD33: 175 | AE33: 55 | AF33: 34 | AG33: 31 | AH33: 29 | AI33: 22 | AJ33: 15 | AK33: 13 | AL33: 12 | AM33: 55
A34: BLOCK 3 | B34: 7 | C34: SQUARE | E34: 15 | G34: 100 | H34: 7 | I34: 7 | J34: 580 | K34: =IF(COUNT(J34,I34)=0,"",IFERROR(J34/1000/I34,"")) -> 0.082857143 | L34: 1.07 | M34: =IF(COUNT(H34,L34)=0,"",IFERROR(H34*L34,"")) -> 7.49 | N34: 13.67 | O34: 4.806 | P34: 2.85 | Q34: =IF(COUNT(O34,P34)=0,"",IFERROR(O34*1000/P34*1000,"")) -> 1686315.8 | S34: =IF(COUNT(O34,P34)=0,"",IFERROR(O34*P34,"")) -> 13.6971 | T34: 60.4 | U34: =IF(COUNT(T34)=0,"",IFERROR(COS(T34/180*PI()),"")) -> 0.49394187 | V34: =IF(COUNT(S34,T34)=0,"",IFERROR(S34*COS(T34/360*2*3.14),"")) -> 6.7719349 | W34: =IF(COUNT(V34,M34)=0,"",IFERROR(1-V34/M34,"")) -> 0.095869836 | X34: 6.781 | Y34: 0.497 | Z34: =IFERROR(IF(OR(V34="",X34="",X34=0),"",(V34-X34)/X34*100),"") -> -0.13368344 | AA34: =IF(COUNT(AD34,AE34,AF34,AG34,AH34,AI34,AJ34,AK34,AL34,AC34)=0,"",IFERROR(SQRT(AD34^2+AE34^2+AF34^2+AG34^2+AH34^2+AI34^2+AJ34^2+AK34^2+AL34^2)/AC34,"")) -> 0.061465674 | AC34: 4764 | AD34: 181 | AE34: 181 | AF34: 92 | AG34: 86 | AH34: 45 | AI34: 32 | AJ34: 25 | AK34: 20 | AL34: 17 | AM34: 64
A35: BLOCK 3 | B35: 8 | C35: SQUARE | E35: 15 | G35: 100 | H35: 8 | I35: 8 | J35: 740 | K35: =IF(COUNT(J35,I35)=0,"",IFERROR(J35/1000/I35,"")) -> 0.0925 | L35: 1.13 | M35: =IF(COUNT(H35,L35)=0,"",IFERROR(H35*L35,"")) -> 9.04 | N35: 15.79 | O35: 5.582 | P35: 3.373 | Q35: =IF(COUNT(O35,P35)=0,"",IFERROR(O35*1000/P35*1000,"")) -> 1654906.6 | S35: =IF(COUNT(O35,P35)=0,"",IFERROR(O35*P35,"")) -> 18.828086 | T35: 61.2 | U35: =IF(COUNT(T35)=0,"",IFERROR(COS(T35/180*PI()),"")) -> 0.48175367 | V35: =IF(COUNT(S35,T35)=0,"",IFERROR(S35*COS(T35/360*2*3.14),"")) -> 9.0794326 | W35: =IF(COUNT(V35,M35)=0,"",IFERROR(1-V35/M35,"")) -> -0.0043620152 | X35: 9.089 | Y35: 0.48 | Z35: =IFERROR(IF(OR(V35="",X35="",X35=0),"",(V35-X35)/X35*100),"") -> -0.10526331 | AA35: =IF(COUNT(AD35,AE35,AF35,AG35,AH35,AI35,AJ35,AK35,AL35,AC35)=0,"",IFERROR(SQRT(AD35^2+AE35^2+AF35^2+AG35^2+AH35^2+AI35^2+AJ35^2+AK35^2+AL35^2)/AC35,"")) -> 0.099635066 | AC35: 5523 | AD35: 437 | AE35: 225 | AF35: 195 | AG35: 126 | AH35: 62 | AI35: 40 | AJ35: 28 | AK35: 27 | AL35: 19 | AM35: 75
A36: BLOCK 3 | B36: 9 | C36: SQUARE | E36: 15 | G36: 100 | H36: 9 | I36: 9 | J36: 900 | K36: =IF(COUNT(J36,I36)=0,"",IFERROR(J36/1000/I36,"")) -> 0.1 | L36: 1.28 | M36: =IF(COUNT(H36,L36)=0,"",IFERROR(H36*L36,"")) -> 11.52 | N36: 18.09 | O36: 5.73 | P36: 3.5 | Q36: =IF(COUNT(O36,P36)=0,"",IFERROR(O36*1000/P36*1000,"")) -> 1637142.9 | S36: =IF(COUNT(O36,P36)=0,"",IFERROR(O36*P36,"")) -> 20.055 | T36: 61.5 | U36: =IF(COUNT(T36)=0,"",IFERROR(COS(T36/180*PI()),"")) -> 0.47715876 | V36: =IF(COUNT(S36,T36)=0,"",IFERROR(S36*COS(T36/360*2*3.14),"")) -> 9.5790081 | W36: =IF(COUNT(V36,M36)=0,"",IFERROR(1-V36/M36,"")) -> 0.16848888 | X36: 10.09 | Y36: 0.475 | Z36: =IFERROR(IF(OR(V36="",X36="",X36=0),"",(V36-X36)/X36*100),"") -> -5.0643399 | AA36: =IF(COUNT(AD36,AE36,AF36,AG36,AH36,AI36,AJ36,AK36,AL36,AC36)=0,"",IFERROR(SQRT(AD36^2+AE36^2+AF36^2+AG36^2+AH36^2+AI36^2+AJ36^2+AK36^2+AL36^2)/AC36,"")) -> 0.12882832 | AC36: 6303 | AD36: 655 | AE36: 384 | AF36: 215 | AG36: 158 | AH36: 80 | AI36: 47 | AJ36: 38 | AK36: 30 | AL36: 27 | AM36: 85
A37: BLOCK 3 | B37: 10 | C37: SQUARE | E37: 15 | G37: 100 | H37: 10 | I37: 10 | J37: 1421 | K37: =IF(COUNT(J37,I37)=0,"",IFERROR(J37/1000/I37,"")) -> 0.1421 | L37: 1.38 | M37: =IF(COUNT(H37,L37)=0,"",IFERROR(H37*L37,"")) -> 13.8 | N37: 20.57 | O37: 7.18 | P37: 4.61 | Q37: =IF(COUNT(O37,P37)=0,"",IFERROR(O37*1000/P37*1000,"")) -> 1557483.7 | S37: =IF(COUNT(O37,P37)=0,"",IFERROR(O37*P37,"")) -> 33.0998 | T37: 63.53 | U37: =IF(COUNT(T37)=0,"",IFERROR(COS(T37/180*PI()),"")) -> 0.44572917 | V37: =IF(COUNT(S37,T37)=0,"",IFERROR(S37*COS(T37/360*2*3.14),"")) -> 14.770199 | W37: =IF(COUNT(V37,M37)=0,"",IFERROR(1-V37/M37,"")) -> -0.070304304 | X37: 14.78 | Y37: 0.444 | Z37: =IFERROR(IF(OR(V37="",X37="",X37=0),"",(V37-X37)/X37*100),"") -> -0.066309928 | AA37: =IF(COUNT(AD37,AE37,AF37,AG37,AH37,AI37,AJ37,AK37,AL37,AC37)=0,"",IFERROR(SQRT(AD37^2+AE37^2+AF37^2+AG37^2+AH37^2+AI37^2+AJ37^2+AK37^2+AL37^2)/AC37,"")) -> 0.17116145 | AC37: 7044 | AD37: 906 | AE37: 550 | AF37: 523 | AG37: 195 | AH37: 90 | AI37: 60 | AJ37: 52 | AK37: 47 | AL37: 46 | AM37: 94
A38: BLOCK 4 — Probe load (open circuit) · Freq-sweep 5→60 kHz · 2 V · DC 100% · SQUARE
A39: BLOCK 4 | B39: 1 | C39: SQUARE | E39: 5 | G39: 100 | H39: 2 | I39: 1.995 | J39: 85 | K39: =IF(COUNT(J39,I39)=0,"",IFERROR(J39/1000/I39,"")) -> 0.042606516 | L39: 0.47 | M39: =IF(COUNT(H39,L39)=0,"",IFERROR(H39*L39,"")) -> 0.94 | N39: 3.43 | O39: 1 | P39: 0.345 | Q39: =IF(COUNT(O39,P39)=0,"",IFERROR(O39*1000/P39*1000,"")) -> 2898550.7 | S39: =IF(COUNT(O39,P39)=0,"",IFERROR(O39*P39,"")) -> 0.345 | T39: 74 | U39: =IF(COUNT(T39)=0,"",IFERROR(COS(T39/180*PI()),"")) -> 0.27563736 | V39: =IF(COUNT(S39,T39)=0,"",IFERROR(S39*COS(T39/360*2*3.14),"")) -> 0.095312008 | W39: =IF(COUNT(V39,M39)=0,"",IFERROR(1-V39/M39,"")) -> 0.89860425 | Z39: =IFERROR(IF(OR(V39="",X39="",X39=0),"",(V39-X39)/X39*100),"") | AA39: =IF(COUNT(AD39,AE39,AF39,AG39,AH39,AI39,AJ39,AK39,AL39,AC39)=0,"",IFERROR(SQRT(AD39^2+AE39^2+AF39^2+AG39^2+AH39^2+AI39^2+AJ39^2+AK39^2+AL39^2)/AC39,"")) -> 0.19928944 | AB39: "Broken" sine | AC39: 891 | AD39: 76 | AE39: 121 | AF39: 66 | AG39: 55 | AH39: 49 | AI39: 29 | AJ39: 15 | AK39: 12 | AL39: 11 | AM39: 26 | AN39: unstable | AQ39: PIC_1815_16052026
A40: BLOCK 4 | B40: 2 | C40: SQUARE | E40: 7.5 | G40: 100 | H40: 2 | I40: 1.97 | J40: 294 | K40: =IF(COUNT(J40,I40)=0,"",IFERROR(J40/1000/I40,"")) -> 0.14923858 | L40: 0.17 | M40: =IF(COUNT(H40,L40)=0,"",IFERROR(H40*L40,"")) -> 0.34 | N40: 4.13 | O40: 1.29 | P40: 0.601 | Q40: =IF(COUNT(O40,P40)=0,"",IFERROR(O40*1000/P40*1000,"")) -> 2146422.6 | S40: =IF(COUNT(O40,P40)=0,"",IFERROR(O40*P40,"")) -> 0.77529 | T40: 83 | U40: =IF(COUNT(T40)=0,"",IFERROR(COS(T40/180*PI()),"")) -> 0.12186934 | V40: =IF(COUNT(S40,T40)=0,"",IFERROR(S40*COS(T40/360*2*3.14),"")) -> 0.095049179 | W40: =IF(COUNT(V40,M40)=0,"",IFERROR(1-V40/M40,"")) -> 0.72044359 | Z40: =IFERROR(IF(OR(V40="",X40="",X40=0),"",(V40-X40)/X40*100),"") | AA40: =IF(COUNT(AD40,AE40,AF40,AG40,AH40,AI40,AJ40,AK40,AL40,AC40)=0,"",IFERROR(SQRT(AD40^2+AE40^2+AF40^2+AG40^2+AH40^2+AI40^2+AJ40^2+AK40^2+AL40^2)/AC40,"")) -> 0.30625124 | AB40: Distorted sine | AC40: 1212 | AD40: 339 | AE40: 125 | AF40: 78 | AG40: 22 | AH40: 18 | AI40: 11 | AJ40: 10 | AK40: 8 | AL40: 7 | AM40: 26 | AN40: stable | AQ40: PIC_1816_16052026
...

Sheet Exp 2.1 - DBD_V_sweep
A1: Exp 2.1 - DBD V sweep
A2: CONDITIONS | I2: PRIMARY | N2: HV SECONDARY | R2: POWER | AA2: SIGNAL QUALITY | AM2: PHYSICAL STATE | AQ2: TRACEABILITY
A3: Block | B3: Step | C3: Mode | D3: Turns/branch | E3: Frequency (kHz) | F3: Burst Frequency (kHz) | G3: DutyCycle (%) | H3: V_Buck setpoint (V) | I3: V_Buck_Average (V) | J3: V_Buck_Ripple (mV) | K3: Relative_Ripple (%) | L3: I_primary (A) | M3: P_input (W) | N3: V_secondary_pp (kV) | O3: V_secondary_RMS (kV) | P3: I_sec_RMS (mA) | Q3: Load_Impedance (Ohm) | R3: VxI_RMS (W) | S3: Apparent Power (VA) | T3: Phase Angle° | U3: Power factor | V3: Real Power(W) | W3: Loss fraction (1-η) | X3: Real Power_scope (W) | Y3: Power Factor_scope | Z3: cos(φ) vs scope deviation (%) | AA3: THD (%) | AB3: Waveform | AC3: V1 (Vrms) | AD3: V2 | AE3: V3 | AF3: V4 | AG3: V5 | AH3: V6 | AI3: V7 | AJ3: V8 | AK3: V9 | AL3: V10 | AM3: T_MOSFET (°C) | AN3: Stability | AO3: Plasma state | AP3: Ignition threshold? | AQ3: Photo | AR3: Observations
A4: BLOCK 1 — DBD · V-sweep · 5 kHz · DC 100% · SQUARE · 3 turns/branch — reference point: step 7 (6.3 V) (8 steps)
A5: BLOCK 1 | B5: 1 | C5: SQUARE | D5: 3 | E5: 5 | G5: 100 | H5: 1 | I5: 0.991 | J5: 89 | K5: =IF(COUNT(J5,I5)=0,"",IFERROR(J5/1000/I5,"")) -> 0.089808274 | L5: 0.13 | M5: =IF(COUNT(H5,L5)=0,"",IFERROR(H5*L5,"")) -> 0.13 | N5: 1.983 | O5: 0.669 | P5: 0.45 | Q5: =IF(COUNT(O5,P5)=0,"",IFERROR(O5*1000/P5*1000,"")) -> 1486666.7 | S5: =IF(COUNT(O5,P5)=0,"",IFERROR(O5*P5,"")) -> 0.30105 | T5: 72.4 | U5: =IF(COUNT(T5)=0,"",IFERROR(COS(T5/180*PI()),"")) -> 0.30236989 | V5: =IF(COUNT(S5,T5)=0,"",IFERROR(S5*COS(T5/360*2*3.14),"")) -> 0.091212262 | W5: =IF(COUNT(V5,M5)=0,"",IFERROR(1-V5/M5,"")) -> 0.29836721 | Z5: =IFERROR(IF(OR(V5="",X5="",X5=0),"",(V5-X5)/X5*100),"") | AA5: =IF(COUNT(AD5,AE5,AF5,AG5,AH5,AI5,AJ5,AK5,AL5,AC5)=0,"",IFERROR(SQRT(AD5^2+AE5^2+AF5^2+AG5^2+AH5^2+AI5^2+AJ5^2+AK5^2+AL5^2)/AC5,"")) -> 0.24904076 | AB5: distorted sine | AC5: 650 | AD5: 149 | AE5: 56 | AF5: 18 | AG5: 17 | AH5: 13 | AI5: 7 | AJ5: 6 | AM5: 24 | AN5: stable | AO5: 0
A6: BLOCK 1 | B6: 2 | C6: SQUARE | D6: 3 | E6: 5 | G6: 100 | H6: 2 | I6: 1.994 | J6: 93 | K6: =IF(COUNT(J6,I6)=0,"",IFERROR(J6/1000/I6,"")) -> 0.04663992 | L6: 0.3 | M6: =IF(COUNT(H6,L6)=0,"",IFERROR(H6*L6,"")) -> 0.6 | N6: 3.45 | O6: 1.27 | P6: 0.586 | Q6: =IF(COUNT(O6,P6)=0,"",IFERROR(O6*1000/P6*1000,"")) -> 2167235.5 | S6: =IF(COUNT(O6,P6)=0,"",IFERROR(O6*P6,"")) -> 0.74422 | T6: 69.5 | U6: =IF(COUNT(T6)=0,"",IFERROR(COS(T6/180*PI()),"")) -> 0.35020738 | V6: =IF(COUNT(S6,T6)=0,"",IFERROR(S6*COS(T6/360*2*3.14),"")) -> 0.26105996 | W6: =IF(COUNT(V6,M6)=0,"",IFERROR(1-V6/M6,"")) -> 0.56490007 | Z6: =IFERROR(IF(OR(V6="",X6="",X6=0),"",(V6-X6)/X6*100),"") | AA6: =IF(COUNT(AD6,AE6,AF6,AG6,AH6,AI6,AJ6,AK6,AL6,AC6)=0,"",IFERROR(SQRT(AD6^2+AE6^2+AF6^2+AG6^2+AH6^2+AI6^2+AJ6^2+AK6^2+AL6^2)/AC6,"")) -> 0.11728272 | AB6: sine | AC6: 1268 | AD6: 133 | AE6: 49 | AF6: 35 | AG6: 24 | AH6: 12 | AI6: 9 | AM6: 25 | AN6: stable | AO6: 0
A7: BLOCK 1 | B7: 3 | C7: SQUARE | D7: 3 | E7: 5 | G7: 100 | H7: 3 | I7: 2.98 | J7: 129 | K7: =IF(COUNT(J7,I7)=0,"",IFERROR(J7/1000/I7,"")) -> 0.043288591 | L7: 0.51 | M7: =IF(COUNT(H7,L7)=0,"",IFERROR(H7*L7,"")) -> 1.53 | N7: 4.01 | O7: 1.54 | P7: 0.747 | Q7: =IF(COUNT(O7,P7)=0,"",IFERROR(O7*1000/P7*1000,"")) -> 2061579.7 | S7: =IF(COUNT(O7,P7)=0,"",IFERROR(O7*P7,"")) -> 1.15038 | T7: 68.4 | U7: =IF(COUNT(T7)=0,"",IFERROR(COS(T7/180*PI()),"")) -> 0.36812455 | V7: =IF(COUNT(S7,T7)=0,"",IFERROR(S7*COS(T7/360*2*3.14),"")) -> 0.42413037 | W7: =IF(COUNT(V7,M7)=0,"",IFERROR(1-V7/M7,"")) -> 0.72279061 | Z7: =IFERROR(IF(OR(V7="",X7="",X7=0),"",(V7-X7)/X7*100),"") | AA7: =IF(COUNT(AD7,AE7,AF7,AG7,AH7,AI7,AJ7,AK7,AL7,AC7)=0,"",IFERROR(SQRT(AD7^2+AE7^2+AF7^2+AG7^2+AH7^2+AI7^2+AJ7^2+AK7^2+AL7^2)/AC7,"")) -> 0.12821283 | AB7: sine | AC7: 1539 | AD7: 175 | AE7: 75 | AF7: 44 | AG7: 18 | AH7: 12 | AI7: 10 | AJ7: 9 | AK7: 8 | AL7: 6 | AM7: 26 | AN7: stable | AO7: 0
A8: BLOCK 1 | B8: 4 | C8: SQUARE | D8: 3 | E8: 5 | G8: 100 | H8: 4 | I8: 3.98 | J8: 155 | K8: =IF(COUNT(J8,I8)=0,"",IFERROR(J8/1000/I8,"")) -> 0.038944724 | L8: 0.73 | M8: =IF(COUNT(H8,L8)=0,"",IFERROR(H8*L8,"")) -> 2.92 | N8: 4.5 | O8: 1.71 | P8: 0.987 | Q8: =IF(COUNT(O8,P8)=0,"",IFERROR(O8*1000/P8*1000,"")) -> 1732522.8 | S8: =IF(COUNT(O8,P8)=0,"",IFERROR(O8*P8,"")) -> 1.68777 | T8: 72.3 | U8: =IF(COUNT(T8)=0,"",IFERROR(COS(T8/180*PI()),"")) -> 0.30403306 | V8: =IF(COUNT(S8,T8)=0,"",IFERROR(S8*COS(T8/360*2*3.14),"")) -> 0.51416636 | W8: =IF(COUNT(V8,M8)=0,"",IFERROR(1-V8/M8,"")) -> 0.82391563 | Z8: =IFERROR(IF(OR(V8="",X8="",X8=0),"",(V8-X8)/X8*100),"") | AA8: =IF(COUNT(AD8,AE8,AF8,AG8,AH8,AI8,AJ8,AK8,AL8,AC8)=0,"",IFERROR(SQRT(AD8^2+AE8^2+AF8^2+AG8^2+AH8^2+AI8^2+AJ8^2+AK8^2+AL8^2)/AC8,"")) -> 0.18284422 | AB8: sine | AC8: 1708 | AD8: 238 | AE8: 183 | AF8: 72 | AG8: 36 | AH8: 19 | AI8: 16 | AJ8: 10 | AK8: 10 | AL8: 10 | AM8: 29 | AN8: stable | AO8: 1 | AP8: YES | AQ8: PIC_1840_18052026
A9: BLOCK 1 | B9: 5 | C9: SQUARE | D9: 3 | E9: 5 | G9: 100 | H9: 5 | I9: 4.96 | J9: 253 | K9: =IF(COUNT(J9,I9)=0,"",IFERROR(J9/1000/I9,"")) -> 0.051008065 | L9: 1.48 | M9: =IF(COUNT(H9,L9)=0,"",IFERROR(H9*L9,"")) -> 7.4 | N9: 6.47 | O9: 2.27 | P9: 1.96 | Q9: =IF(COUNT(O9,P9)=0,"",IFERROR(O9*1000/P9*1000,"")) -> 1158163.3 | S9: =IF(COUNT(O9,P9)=0,"",IFERROR(O9*P9,"")) -> 4.4492 | T9: 70 | U9: =IF(COUNT(T9)=0,"",IFERROR(COS(T9/180*PI()),"")) -> 0.34202014 | V9: =IF(COUNT(S9,T9)=0,"",IFERROR(S9*COS(T9/360*2*3.14),"")) -> 1.5243052 | W9: =IF(COUNT(V9,M9)=0,"",IFERROR(1-V9/M9,"")) -> 0.79401281 | Z9: =IFERROR(IF(OR(V9="",X9="",X9=0),"",(V9-X9)/X9*100),"") | AA9: =IF(COUNT(AD9,AE9,AF9,AG9,AH9,AI9,AJ9,AK9,AL9,AC9)=0,"",IFERROR(SQRT(AD9^2+AE9^2+AF9^2+AG9^2+AH9^2+AI9^2+AJ9^2+AK9^2+AL9^2)/AC9,"")) -> 0.18101964 | AB9: sine | AC9: 2242 | AD9: 321 | AE9: 199 | AF9: 121 | AG9: 67 | AH9: 38 | AI9: 27 | AJ9: 21 | AK9: 15 | AL9: 10 | AM9: 34 | AN9: unstable | AO9: 1
A10: BLOCK 1 | B10: 6 | C10: SQUARE | D10: 3 | E10: 5 | G10: 100 | H10: 6 | I10: 5.96 | J10: 491 | K10: =IF(COUNT(J10,I10)=0,"",IFERROR(J10/1000/I10,"")) -> 0.08238255 | L10: 1.78 | M10: =IF(COUNT(H10,L10)=0,"",IFERROR(H10*L10,"")) -> 10.68 | N10: 8.21 | O10: 3.035 | P10: 3.168 | Q10: =IF(COUNT(O10,P10)=0,"",IFERROR(O10*1000/P10*1000,"")) -> 958017.68 | R10: 6.8 | S10: =IF(COUNT(O10,P10)=0,"",IFERROR(O10*P10,"")) -> 9.61488 | T10: 73.9 | U10: =IF(COUNT(T10)=0,"",IFERROR(COS(T10/180*PI()),"")) -> 0.27731465 | V10: =IF(COUNT(S10,T10)=0,"",IFERROR(S10*COS(T10/360*2*3.14),"")) -> 2.6723869 | W10: =IF(COUNT(V10,M10)=0,"",IFERROR(1-V10/M10,"")) -> 0.74977651 | Z10: =IFERROR(IF(OR(V10="",X10="",X10=0),"",(V10-X10)/X10*100),"") | AA10: =IF(COUNT(AD10,AE10,AF10,AG10,AH10,AI10,AJ10,AK10,AL10,AC10)=0,"",IFERROR(SQRT(AD10^2+AE10^2+AF10^2+AG10^2+AH10^2+AI10^2+AJ10^2+AK10^2+AL10^2)/AC10,"")) -> 0.18826667 | AB10: slightly distorted sine | AC10: 2961 | AD10: 446 | AE10: 209 | AF10: 175 | AG10: 153 | AH10: 71 | AI10: 53 | AJ10: 53 | AK10: 45 | AL10: 38 | AM10: 50 | AN10: unstable | AO10: 1 | AR10: Sudden current increase, then decrease -> impedance change?
A11: BLOCK 1 | B11: 7 | C11: SQUARE | D11: 3 | E11: 5 | G11: 100 | H11: 6.3 | I11: 6.24 | J11: 582 | K11: =IF(COUNT(J11,I11)=0,"",IFERROR(J11/1000/I11,"")) -> 0.093269231 | L11: 1.89 | M11: =IF(COUNT(H11,L11)=0,"",IFERROR(H11*L11,"")) -> 11.907 | N11: 8.69 | O11: 3.25 | P11: 3.483 | Q11: =IF(COUNT(O11,P11)=0,"",IFERROR(O11*1000/P11*1000,"")) -> 933103.65 | R11: 7.56 | S11: =IF(COUNT(O11,P11)=0,"",IFERROR(O11*P11,"")) -> 11.31975 | T11: 74.9 | U11: =IF(COUNT(T11)=0,"",IFERROR(COS(T11/180*PI()),"")) -> 0.26050451 | V11: =IF(COUNT(S11,T11)=0,"",IFERROR(S11*COS(T11/360*2*3.14),"")) -> 2.9560881 | W11: =IF(COUNT(V11,M11)=0,"",IFERROR(1-V11/M11,"")) -> 0.75173528 | Z11: =IFERROR(IF(OR(V11="",X11="",X11=0),"",(V11-X11)/X11*100),"") | AA11: =IF(COUNT(AD11,AE11,AF11,AG11,AH11,AI11,AJ11,AK11,AL11,AC11)=0,"",IFERROR(SQRT(AD11^2+AE11^2+AF11^2+AG11^2+AH11^2+AI11^2+AJ11^2+AK11^2+AL11^2)/AC11,"")) -> 0.20006202 | AB11: slightly distorted sine | AC11: 3158 | AD11: 502 | AE11: 232 | AF11: 209 | AG11: 180 | AH11: 86 | AI11: 69 | AJ11: 50 | AK11: 38 | AL11: 34 | AM11: 51 | AN11: stable | AO11: 1
A12: BLOCK 1 | B12: 8 | C12: SQUARE | D12: 3 | E12: 5 | G12: 100 | H12: 7 | I12: 6.96 | J12: 335 | K12: =IF(COUNT(J12,I12)=0,"",IFERROR(J12/1000/I12,"")) -> 0.048132184 | L12: 3.01 | M12: =IF(COUNT(H12,L12)=0,"",IFERROR(H12*L12,"")) -> 21.07 | N12: 10.03 | O12: 3.75 | P12: 4.59 | Q12: =IF(COUNT(O12,P12)=0,"",IFERROR(O12*1000/P12*1000,"")) -> 816993.46 | R12: 11.56 | S12: =IF(COUNT(O12,P12)=0,"",IFERROR(O12*P12,"")) -> 17.2125 | T12: 88.4 | U12: =IF(COUNT(T12)=0,"",IFERROR(COS(T12/180*PI()),"")) -> 0.027921639 | V12: =IF(COUNT(S12,T12)=0,"",IFERROR(S12*COS(T12/360*2*3.14),"")) -> 0.49405891 | W12: =IF(COUNT(V12,M12)=0,"",IFERROR(1-V12/M12,"")) -> 0.97655155 | Z12: =IFERROR(IF(OR(V12="",X12="",X12=0),"",(V12-X12)/X12*100),"") | AA12: =IF(COUNT(AD12,AE12,AF12,AG12,AH12,AI12,AJ12,AK12,AL12,AC12)=0,"",IFERROR(SQRT(AD12^2+AE12^2+AF12^2+AG12^2+AH12^2+AI12^2+AJ12^2+AK12^2+AL12^2)/AC12,"")) -> 0.30830999 | AB12: strongly distorted sine | AC12: 3559 | AD12: 623 | AE12: 573 | AF12: 442 | AG12: 357 | AH12: 311 | AI12: 204 | AJ12: 144 | AK12: 65 | AL12: 38 | AM12: 69 | AN12: stable | AO12: 1 | AQ12: PIC_1245_19052026 | AR12: close to the current limit (current keeps rising slightly)
A13: BLOCK 2 — DBD · V-sweep · 5 kHz · PULSE 1kHz@10%DC · 3 turns/branch (harmonics V1–V10 not recorded for steps 6–8; stopped above 20 V, buck limit)
A14: BLOCK 2 | B14: 1 | C14: PULSE | D14: 3 | E14: 5 | F14: 1 | G14: 10 | H14: 1 | J14: 215 | K14: =IF(COUNT(J14,I14)=0,"",IFERROR(J14/1000/I14,"")) | L14: 0.06 | M14: =IF(COUNT(H14,L14)=0,"",IFERROR(H14*L14,"")) -> 0.06 | N14: 1.79 | O14: 0.21 | P14: 0.096 | Q14: =IF(COUNT(O14,P14)=0,"",IFERROR(O14*1000/P14*1000,"")) -> 2187500 | R14: 0.047 | S14: =IF(COUNT(O14,P14)=0,"",IFERROR(O14*P14,"")) -> 0.02016 | T14: 77.8 | U14: =IF(COUNT(T14)=0,"",IFERROR(COS(T14/180*PI()),"")) -> 0.2113248 | V14: =IF(COUNT(S14,T14)=0,"",IFERROR(S14*COS(T14/360*2*3.14),"")) -> 0.0042738712 | W14: =IF(COUNT(V14,M14)=0,"",IFERROR(1-V14/M14,"")) -> 0.92876881 | Z14: =IFERROR(IF(OR(V14="",X14="",X14=0),"",(V14-X14)/X14*100),"") | AA14: =IF(COUNT(AD14,AE14,AF14,AG14,AH14,AI14,AJ14,AK14,AL14,AC14)=0,"",IFERROR(SQRT(AD14^2+AE14^2+AF14^2+AG14^2+AH14^2+AI14^2+AJ14^2+AK14^2+AL14^2)/AC14,"")) -> 2.4832699 | AB14: Pulse with damping | AC14: 67 | AD14: 67 | AE14: 64 | AF14: 61 | AG14: 57 | AH14: 55 | AI14: 51 | AJ14: 46 | AK14: 52 | AL14: 41 | AM14: 24 | AN14: stable | AO14: 0 | AQ14: PIC_1814_19052026
A15: BLOCK 2 | B15: 2 | C15: PULSE | D15: 3 | E15: 5 | F15: 1 | G15: 10 | H15: 2 | J15: 199 | K15: =IF(COUNT(J15,I15)=0,"",IFERROR(J15/1000/I15,"")) | L15: 0.08 | M15: =IF(COUNT(H15,L15)=0,"",IFERROR(H15*L15,"")) -> 0.16 | N15: 1.98 | O15: 0.237 | P15: 0.104 | Q15: =IF(COUNT(O15,P15)=0,"",IFERROR(O15*1000/P15*1000,"")) -> 2278846.2 | R15: 0.072 | S15: =IF(COUNT(O15,P15)=0,"",IFERROR(O15*P15,"")) -> 0.024648 | T15: 72 | U15: =IF(COUNT(T15)=0,"",IFERROR(COS(T15/180*PI()),"")) -> 0.30901699 | V15: =IF(COUNT(S15,T15)=0,"",IFERROR(S15*COS(T15/360*2*3.14),"")) -> 0.0076315831 | W15: =IF(COUNT(V15,M15)=0,"",IFERROR(1-V15/M15,"")) -> 0.95230261 | Z15: =IFERROR(IF(OR(V15="",X15="",X15=0),"",(V15-X15)/X15*100),"") | AA15: =IF(COUNT(AD15,AE15,AF15,AG15,AH15,AI15,AJ15,AK15,AL15,AC15)=0,"",IFERROR(SQRT(AD15^2+AE15^2+AF15^2+AG15^2+AH15^2+AI15^2+AJ15^2+AK15^2+AL15^2)/AC15,"")) -> 2.4354409 | AC15: 102 | AD15: 96 | AE15: 95 | AF15: 89 | AG15: 86 | AH15: 87 | AI15: 83 | AJ15: 75 | AK15: 65 | AL15: 62 | AM15: 24 | AN15: stable | AO15: 0
A16: BLOCK 2 | B16: 3 | C16: PULSE | D16: 3 | E16: 5 | F16: 1 | G16: 10 | H16: 3 | J16: 355 | K16: =IF(COUNT(J16,I16)=0,"",IFERROR(J16/1000/I16,"")) | L16: 0.08 | M16: =IF(COUNT(H16,L16)=0,"",IFERROR(H16*L16,"")) -> 0.24 | N16: 3.93 | O16: 0.455 | P16: 0.163 | Q16: =IF(COUNT(O16,P16)=0,"",IFERROR(O16*1000/P16*1000,"")) -> 2791411 | R16: 0.151 | S16: =IF(COUNT(O16,P16)=0,"",IFERROR(O16*P16,"")) -> 0.074165 | T16: 68 | U16: =IF(COUNT(T16)=0,"",IFERROR(COS(T16/180*PI()),"")) -> 0.37460659 | V16: =IF(COUNT(S16,T16)=0,"",IFERROR(S16*COS(T16/360*2*3.14),"")) -> 0.027824067 | W16: =IF(COUNT(V16,M16)=0,"",IFERROR(1-V16/M16,"")) -> 0.88406639 | Z16: =IFERROR(IF(OR(V16="",X16="",X16=0),"",(V16-X16)/X16*100),"") | AA16: =IF(COUNT(AD16,AE16,AF16,AG16,AH16,AI16,AJ16,AK16,AL16,AC16)=0,"",IFERROR(SQRT(AD16^2+AE16^2+AF16^2+AG16^2+AH16^2+AI16^2+AJ16^2+AK16^2+AL16^2)/AC16,"")) -> 2.3258994 | AC16: 162 | AD16: 151 | AE16: 150 | AF16: 142 | AG16: 135 | AH16: 133 | AI16: 116 | AJ16: 108 | AK16: 100 | AL16: 74 | AM16: 24 | AN16: stable | AO16: 0
A17: BLOCK 2 | B17: 4 | C17: PULSE | D17: 3 | E17: 5 | F17: 1 | G17: 10 | H17: 4 | J17: 359 | K17: =IF(COUNT(J17,I17)=0,"",IFERROR(J17/1000/I17,"")) | L17: 0.09 | M17: =IF(COUNT(H17,L17)=0,"",IFERROR(H17*L17,"")) -> 0.36 | N17: 3.95 | O17: 0.457 | P17: 0.164 | Q17: =IF(COUNT(O17,P17)=0,"",IFERROR(O17*1000/P17*1000,"")) -> 2786585.4 | R17: 0.153 | S17: =IF(COUNT(O17,P17)=0,"",IFERROR(O17*P17,"")) -> 0.074948 | T17: 68 | U17: =IF(COUNT(T17)=0,"",IFERROR(COS(T17/180*PI()),"")) -> 0.37460659 | V17: =IF(COUNT(S17,T17)=0,"",IFERROR(S17*COS(T17/360*2*3.14),"")) -> 0.02811782 | W17: =IF(COUNT(V17,M17)=0,"",IFERROR(1-V17/M17,"")) -> 0.92189494 | Z17: =IFERROR(IF(OR(V17="",X17="",X17=0),"",(V17-X17)/X17*100),"") | AA17: =IF(COUNT(AD17,AE17,AF17,AG17,AH17,AI17,AJ17,AK17,AL17,AC17)=0,"",IFERROR(SQRT(AD17^2+AE17^2+AF17^2+AG17^2+AH17^2+AI17^2+AJ17^2+AK17^2+AL17^2)/AC17,"")) -> 2.3121669 | AC17: 165 | AD17: 154 | AE17: 154 | AF17: 143 | AG17: 136 | AH17: 134 | AI17: 119 | AJ17: 105 | AK17: 102 | AL17: 75 | AM17: 25 | AN17: stable | AO17: 0
A18: BLOCK 2 | B18: 5 | C18: PULSE | D18: 3 | E18: 5 | F18: 1 | G18: 10 | H18: 5 | J18: 371 | K18: =IF(COUNT(J18,I18)=0,"",IFERROR(J18/1000/I18,"")) | L18: 0.09 | M18: =IF(COUNT(H18,L18)=0,"",IFERROR(H18*L18,"")) -> 0.45 | N18: 3.98 | O18: 0.464 | P18: 0.169 | Q18: =IF(COUNT(O18,P18)=0,"",IFERROR(O18*1000/P18*1000,"")) -> 2745562.1 | R18: 0.16 | S18: =IF(COUNT(O18,P18)=0,"",IFERROR(O18*P18,"")) -> 0.078416 | T18: 68 | U18: =IF(COUNT(T18)=0,"",IFERROR(COS(T18/180*PI()),"")) -> 0.37460659 | V18: =IF(COUNT(S18,T18)=0,"",IFERROR(S18*COS(T18/360*2*3.14),"")) -> 0.02941889 | W18: =IF(COUNT(V18,M18)=0,"",IFERROR(1-V18/M18,"")) -> 0.93462469 | Z18: =IFERROR(IF(OR(V18="",X18="",X18=0),"",(V18-X18)/X18*100),"") | AA18: =IF(COUNT(AD18,AE18,AF18,AG18,AH18,AI18,AJ18,AK18,AL18,AC18)=0,"",IFERROR(SQRT(AD18^2+AE18^2+AF18^2+AG18^2+AH18^2+AI18^2+AJ18^2+AK18^2+AL18^2)/AC18,"")) -> 2.3356953 | AC18: 166 | AD18: 157 | AE18: 156 | AF18: 145 | AG18: 139 | AH18: 135 | AI18: 121 | AJ18: 105 | AK18: 105 | AL18: 78 | AM18: 25 | AN18: stable | AO18: 0
A19: BLOCK 2 | B19: 6 | C19: PULSE | D19: 3 | E19: 5 | F19: 1 | G19: 10 | H19: 10 | J19: 566 | K19: =IF(COUNT(J19,I19)=0,"",IFERROR(J19/1000/I19,"")) | L19: 0.09 | M19: =IF(COUNT(H19,L19)=0,"",IFERROR(H19*L19,"")) -> 0.9 | N19: 4.48 | O19: 0.52 | P19: 0.227 | Q19: =IF(COUNT(O19,P19)=0,"",IFERROR(O19*1000/P19*1000,"")) -> 2290748.9 | R19: 0.222 | S19: =IF(COUNT(O19,P19)=0,"",IFERROR(O19*P19,"")) -> 0.11804 | T19: 72 | U19: =IF(COUNT(T19)=0,"",IFERROR(COS(T19/180*PI()),"")) -> 0.30901699 | V19: =IF(COUNT(S19,T19)=0,"",IFERROR(S19*COS(T19/360*2*3.14),"")) -> 0.036547877 | W19: =IF(COUNT(V19,M19)=0,"",IFERROR(1-V19/M19,"")) -> 0.95939125 | Z19: =IFERROR(IF(OR(V19="",X19="",X19=0),"",(V19-X19)/X19*100),"") | AA19: =IF(COUNT(AD19,AE19,AF19,AG19,AH19,AI19,AJ19,AK19,AL19,AC19)=0,"",IFERROR(SQRT(AD19^2+AE19^2+AF19^2+AG19^2+AH19^2+AI19^2+AJ19^2+AK19^2+AL19^2)/AC19,""))
A20: BLOCK 2 | B20: 7 | C20: PULSE | D20: 3 | E20: 5 | F20: 1 | G20: 10 | H20: 15 | J20: 566 | K20: =IF(COUNT(J20,I20)=0,"",IFERROR(J20/1000/I20,"")) | L20: 0.1 | M20: =IF(COUNT(H20,L20)=0,"",IFERROR(H20*L20,"")) -> 1.5 | N20: 4.67 | O20: 0.531 | P20: 0.229 | Q20: =IF(COUNT(O20,P20)=0,"",IFERROR(O20*1000/P20*1000,"")) -> 2318777.3 | R20: 0.241 | S20: =IF(COUNT(O20,P20)=0,"",IFERROR(O20*P20,"")) -> 0.121599 | T20: 68.5 | U20: =IF(COUNT(T20)=0,"",IFERROR(COS(T20/180*PI()),"")) -> 0.36650123 | V20: =IF(COUNT(S20,T20)=0,"",IFERROR(S20*COS(T20/360*2*3.14),"")) -> 0.044634747 | W20: =IF(COUNT(V20,M20)=0,"",IFERROR(1-V20/M20,"")) -> 0.9702435 | Z20: =IFERROR(IF(OR(V20="",X20="",X20=0),"",(V20-X20)/X20*100),"") | AA20: =IF(COUNT(AD20,AE20,AF20,AG20,AH20,AI20,AJ20,AK20,AL20,AC20)=0,"",IFERROR(SQRT(AD20^2+AE20^2+AF20^2+AG20^2+AH20^2+AI20^2+AJ20^2+AK20^2+AL20^2)/AC20,""))
A21: BLOCK 2 | B21: 8 | C21: PULSE | D21: 3 | E21: 5 | F21: 1 | G21: 10 | H21: 20 | J21: 582 | K21: =IF(COUNT(J21,I21)=0,"",IFERROR(J21/1000/I21,"")) | L21: 0.1 | M21: =IF(COUNT(H21,L21)=0,"",IFERROR(H21*L21,"")) -> 2 | N21: 4.75 | O21: 0.539 | P21: 0.238 | Q21: =IF(COUNT(O21,P21)=0,"",IFERROR(O21*1000/P21*1000,"")) -> 2264705.9 | R21: 0.256 | S21: =IF(COUNT(O21,P21)=0,"",IFERROR(O21*P21,"")) -> 0.128282 | T21: 68.5 | U21: =IF(COUNT(T21)=0,"",IFERROR(COS(T21/180*PI()),"")) -> 0.36650123 | V21: =IF(COUNT(S21,T21)=0,"",IFERROR(S21*COS(T21/360*2*3.14),"")) -> 0.047087842 | W21: =IF(COUNT(V21,M21)=0,"",IFERROR(1-V21/M21,"")) -> 0.97645608 | Z21: =IFERROR(IF(OR(V21="",X21="",X21=0),"",(V21-X21)/X21*100),"") | AA21: =IF(COUNT(AD21,AE21,AF21,AG21,AH21,AI21,AJ21,AK21,AL21,AC21)=0,"",IFERROR(SQRT(AD21^2+AE21^2+AF21^2+AG21^2+AH21^2+AI21^2+AJ21^2+AK21^2+AL21^2)/AC21,""))
A22: BLOCK 3 — DBD · V-sweep · 5 kHz · DC 50% · SQUARE · 3 turns/branch (9 steps)
A23: BLOCK 3 | B23: 1 | C23: SQUARE | D23: 3 | E23: 5 | G23: 50 | H23: 1 | J23: 80 | K23: =IF(COUNT(J23,I23)=0,"",IFERROR(J23/1000/I23,"")) | L23: 0.09 | M23: =IF(COUNT(H23,L23)=0,"",IFERROR(H23*L23,"")) -> 0.09 | N23: 1.77 | O23: 0.624 | P23: 0.219 | Q23: =IF(COUNT(O23,P23)=0,"",IFERROR(O23*1000/P23*1000,"")) -> 2849315.1 | R23: 0.118 | S23: =IF(COUNT(O23,P23)=0,"",IFERROR(O23*P23,"")) -> 0.136656 | T23: 66.8 | U23: =IF(COUNT(T23)=0,"",IFERROR(COS(T23/180*PI()),"")) -> 0.39394191 | V23: =IF(COUNT(S23,T23)=0,"",IFERROR(S23*COS(T23/360*2*3.14),"")) -> 0.053908755 | W23: =IF(COUNT(V23,M23)=0,"",IFERROR(1-V23/M23,"")) -> 0.40101383 | Z23: =IFERROR(IF(OR(V23="",X23="",X23=0),"",(V23-X23)/X23*100),"") | AA23: =IF(COUNT(AD23,AE23,AF23,AG23,AH23,AI23,AJ23,AK23,AL23,AC23)=0,"",IFERROR(SQRT(AD23^2+AE23^2+AF23^2+AG23^2+AH23^2+AI23^2+AJ23^2+AK23^2+AL23^2)/AC23,"")) -> 0.18427253 | AB23: distorted sine | AC23: 606 | AD23: 96 | AE23: 54 | AF23: 13 | AG23: 13 | AM23: 24 | AN23: stable | AO23: 0
A24: BLOCK 3 | B24: 2 | C24: SQUARE | D24: 3 | E24: 5 | G24: 50 | H24: 2 | J24: 140 | K24: =IF(COUNT(J24,I24)=0,"",IFERROR(J24/1000/I24,"")) | L24: 0.1 | M24: =IF(COUNT(H24,L24)=0,"",IFERROR(H24*L24,"")) -> 0.2 | N24: 3.24 | O24: 1.166 | P24: 0.341 | Q24: =IF(COUNT(O24,P24)=0,"",IFERROR(O24*1000/P24*1000,"")) -> 3419354.8 | R24: 0.236 | S24: =IF(COUNT(O24,P24)=0,"",IFERROR(O24*P24,"")) -> 0.397606 | T24: 67.7 | U24: =IF(COUNT(T24)=0,"",IFERROR(COS(T24/180*PI()),"")) -> 0.37945616 | V24: =IF(COUNT(S24,T24)=0,"",IFERROR(S24*COS(T24/360*2*3.14),"")) -> 0.15109438 | W24: =IF(COUNT(V24,M24)=0,"",IFERROR(1-V24/M24,"")) -> 0.24452811 | Z24: =IFERROR(IF(OR(V24="",X24="",X24=0),"",(V24-X24)/X24*100),"") | AA24: =IF(COUNT(AD24,AE24,AF24,AG24,AH24,AI24,AJ24,AK24,AL24,AC24)=0,"",IFERROR(SQRT(AD24^2+AE24^2+AF24^2+AG24^2+AH24^2+AI24^2+AJ24^2+AK24^2+AL24^2)/AC24,"")) -> 0.0971545 | AB24: sine | AC24: 1142 | AD24: 101 | AE24: 42 | AF24: 14 | AG24: 10 | AH24: 7 | AM24: 24 | AN24: stable | AO24: 0
A25: BLOCK 3 | B25: 3 | C25: SQUARE | D25: 3 | E25: 5 | G25: 50 | H25: 3 | J25: 95 | K25: =IF(COUNT(J25,I25)=0,"",IFERROR(J25/1000/I25,"")) | L25: 0.13 | M25: =IF(COUNT(H25,L25)=0,"",IFERROR(H25*L25,"")) -> 0.39 | N25: 3.86 | O25: 1.4 | P25: 0.469 | Q25: =IF(COUNT(O25,P25)=0,"",IFERROR(O25*1000/P25*1000,"")) -> 2985074.6 | R25: 0.593 | S25: =IF(COUNT(O25,P25)=0,"",IFERROR(O25*P25,"")) -> 0.6566 | T25: 64.7 | U25: =IF(COUNT(T25)=0,"",IFERROR(COS(T25/180*PI()),"")) -> 0.42735786 | V25: =IF(COUNT(S25,T25)=0,"",IFERROR(S25*COS(T25/360*2*3.14),"")) -> 0.28094296 | W25: =IF(COUNT(V25,M25)=0,"",IFERROR(1-V25/M25,"")) -> 0.27963344 | Z25: =IFERROR(IF(OR(V25="",X25="",X25=0),"",(V25-X25)/X25*100),"") | AA25: =IF(COUNT(AD25,AE25,AF25,AG25,AH25,AI25,AJ25,AK25,AL25,AC25)=0,"",IFERROR(SQRT(AD25^2+AE25^2+AF25^2+AG25^2+AH25^2+AI25^2+AJ25^2+AK25^2+AL25^2)/AC25,"")) -> 0.083583543 | AB25: sine | AC25: 1378 | AD25: 98 | AE25: 55 | AF25: 22 | AG25: 9 | AH25: 6 | AI25: 6 | AM25: 25 | AN25: stable | AO25: 0
A26: BLOCK 3 | B26: 4 | C26: SQUARE | D26: 3 | E26: 5 | G26: 50 | H26: 4 | J26: 115 | K26: =IF(COUNT(J26,I26)=0,"",IFERROR(J26/1000/I26,"")) | L26: 0.16 | M26: =IF(COUNT(H26,L26)=0,"",IFERROR(H26*L26,"")) -> 0.64 | N26: 4.01 | O26: 1.45 | P26: 0.516 | Q26: =IF(COUNT(O26,P26)=0,"",IFERROR(O26*1000/P26*1000,"")) -> 2810077.5 | R26: 0.7 | S26: =IF(COUNT(O26,P26)=0,"",IFERROR(O26*P26,"")) -> 0.7482 | T26: 65.6 | U26: =IF(COUNT(T26)=0,"",IFERROR(COS(T26/180*PI()),"")) -> 0.41310443 | V26: =IF(COUNT(S26,T26)=0,"",IFERROR(S26*COS(T26/360*2*3.14),"")) -> 0.30948017 | W26: =IF(COUNT(V26,M26)=0,"",IFERROR(1-V26/M26,"")) -> 0.51643723 | Z26: =IFERROR(IF(OR(V26="",X26="",X26=0),"",(V26-X26)/X26*100),"") | AA26: =IF(COUNT(AD26,AE26,AF26,AG26,AH26,AI26,AJ26,AK26,AL26,AC26)=0,"",IFERROR(SQRT(AD26^2+AE26^2+AF26^2+AG26^2+AH26^2+AI26^2+AJ26^2+AK26^2+AL26^2)/AC26,"")) -> 0.084008119 | AB26: sine | AC26: 1432 | AD26: 99 | AE26: 60 | AF26: 28 | AG26: 9 | AH26: 9 | AI26: 8 | AJ26: 6 | AK26: 5 | AM26: 26 | AN26: stable | AO26: 1 | AP26: YES
A27: BLOCK 3 | B27: 5 | C27: SQUARE | D27: 3 | E27: 5 | G27: 50 | H27: 5 | J27: 127 | K27: =IF(COUNT(J27,I27)=0,"",IFERROR(J27/1000/I27,"")) | L27: 0.21 | M27: =IF(COUNT(H27,L27)=0,"",IFERROR(H27*L27,"")) -> 1.05 | N27: 4.13 | O27: 1.48 | P27: 0.558 | Q27: =IF(COUNT(O27,P27)=0,"",IFERROR(O27*1000/P27*1000,"")) -> 2652329.7 | R27: 0.78 | S27: =IF(COUNT(O27,P27)=0,"",IFERROR(O27*P27,"")) -> 0.82584 | T27: 67 | U27: =IF(COUNT(T27)=0,"",IFERROR(COS(T27/180*PI()),"")) -> 0.39073113 | V27: =IF(COUNT(S27,T27)=0,"",IFERROR(S27*COS(T27/360*2*3.14),"")) -> 0.32313199 | W27: =IF(COUNT(V27,M27)=0,"",IFERROR(1-V27/M27,"")) -> 0.69225524 | Z27: =IFERROR(IF(OR(V27="",X27="",X27=0),"",(V27-X27)/X27*100),"") | AA27: =IF(COUNT(AD27,AE27,AF27,AG27,AH27,AI27,AJ27,AK27,AL27,AC27)=0,"",IFERROR(SQRT(AD27^2+AE27^2+AF27^2+AG27^2+AH27^2+AI27^2+AJ27^2+AK27^2+AL27^2)/AC27,"")) -> 0.083921379 | AB27: sine | AC27: 1461 | AD27: 100 | AE27: 61 | AF27: 31 | AG27: 11 | AH27: 9 | AI27: 8 | AJ27: 7 | AK27: 6 | AM27: 27 | AN27: stable | AO27: 1 | AQ27: PIC_1905_19052026 | AR27: noticeable current peak
A28: BLOCK 3 | B28: 6 | C28: SQUARE | D28: 3 | E28: 5 | G28: 50 | H28: 6 | J28: 151 | K28: =IF(COUNT(J28,I28)=0,"",IFERROR(J28/1000/I28,"")) | L28: 0.26 | M28: =IF(COUNT(H28,L28)=0,"",IFERROR(H28*L28,"")) -> 1.56 | N28: 4.21 | O28: 1.51 | P28: 0.603 | Q28: =IF(COUNT(O28,P28)=0,"",IFERROR(O28*1000/P28*1000,"")) -> 2504145.9 | R28: 0.86 | S28: =IF(COUNT(O28,P28)=0,"",IFERROR(O28*P28,"")) -> 0.91053 | T28: 70.6 | U28: =IF(COUNT(T28)=0,"",IFERROR(COS(T28/180*PI()),"")) -> 0.33216113 | V28: =IF(COUNT(S28,T28)=0,"",IFERROR(S28*COS(T28/360*2*3.14),"")) -> 0.30297911 | W28: =IF(COUNT(V28,M28)=0,"",IFERROR(1-V28/M28,"")) -> 0.80578262 | Z28: =IFERROR(IF(OR(V28="",X28="",X28=0),"",(V28-X28)/X28*100),"") | AA28: =IF(COUNT(AD28,AE28,AF28,AG28,AH28,AI28,AJ28,AK28,AL28,AC28)=0,"",IFERROR(SQRT(AD28^2+AE28^2+AF28^2+AG28^2+AH28^2+AI28^2+AJ28^2+AK28^2+AL28^2)/AC28,"")) -> 0.04773647 | AB28: sine | AC28: 1409 | AD28: 65 | AE28: 13 | AF28: 9 | AG28: 7 | AM28: 29 | AN28: stable | AO28: 1
